[2019-03-27 09:14:21,532][Thread-1:140465361909504][task_id:django.server][basehttp.py:136][INFO]["POST /message/mail/ HTTP/1.1" 200 31]
[2019-03-27 09:14:23,941][Thread-3:140465353516800][task_id:mymessage.myviews.Mail_Send][Mail_Send.py:14][INFO][1]
[2019-03-27 09:30:11,616][Thread-1:139796689188608][task_id:django.server][basehttp.py:136][INFO]["POST /message/mail/ HTTP/1.1" 200 31]
[2019-03-27 09:32:44,103][Thread-1:139796689188608][task_id:django.server][basehttp.py:136][INFO]["POST /message/mail/ HTTP/1.1" 200 31]
[2019-03-29 07:23:31,023][Thread-1:140189005354752][task_id:django.server][basehttp.py:136][INFO]["POST /message/mail/ HTTP/1.1" 200 31]
[2019-03-29 07:23:32,343][Thread-3:140188996962048][task_id:mymessage.myviews.Mail_Send][Mail_Send.py:14][INFO][1]
[2019-03-29 07:47:19,276][Thread-1:139842985318144][task_id:django.server][basehttp.py:136][INFO]["POST /message/mail/ HTTP/1.1" 200 31]
[2019-03-29 07:47:20,395][Thread-3:139842976663296][task_id:mymessage.myviews.Mail_Send][Mail_Send.py:14][INFO][1]
[2019-03-29 07:48:39,166][Thread-1:140084109887232][task_id:django.server][basehttp.py:136][INFO]["POST /message/mail/ HTTP/1.1" 200 31]
[2019-03-29 07:48:40,141][Thread-3:140084101494528][task_id:mymessage.myviews.Mail_Send][Mail_Send.py:14][INFO][1]
[2019-03-29 07:50:37,266][Thread-1:140300185089792][task_id:django.server][basehttp.py:136][INFO]["POST /message/mail/ HTTP/1.1" 200 31]
[2019-03-29 07:50:38,326][Thread-3:140300176697088][task_id:mymessage.myviews.Mail_Send][Mail_Send.py:14][INFO][1]
[2019-03-29 07:51:52,833][Thread-1:140300283442944][task_id:django.server][basehttp.py:136][INFO]["POST /message/mail/ HTTP/1.1" 200 31]
[2019-03-29 07:51:54,302][Thread-3:140300206995200][task_id:mymessage.myviews.Mail_Send][Mail_Send.py:14][INFO][1]
[2019-03-29 08:25:48,335][Thread-1:139836577748736][task_id:django.server][basehttp.py:136][INFO]["GET /message/mail/ HTTP/1.1" 200 40]
[2019-03-29 08:28:21,889][Thread-1:139836577748736][task_id:django.server][basehttp.py:136][INFO]["POST /message/mail/ HTTP/1.1" 200 31]
[2019-03-29 08:28:23,074][Thread-3:139836569093888][task_id:mymessage.myviews.Mail_Send][Mail_Send.py:14][INFO][1]
[2019-03-29 08:33:24,111][Thread-1:139836577748736][task_id:django.server][basehttp.py:136][INFO]["POST /message/mail/ HTTP/1.1" 200 31]
[2019-03-29 08:33:25,608][Thread-4:139836569093888][task_id:mymessage.myviews.Mail_Send][Mail_Send.py:14][INFO][1]
[2019-03-29 08:35:38,217][Thread-1:140417826928384][task_id:django.request][log.py:228][ERROR][Internal Server Error: /message/mail/]
Traceback (most recent call last):
  File "/opt/code/env/python/python3-django/venv/lib/python3.7/site-packages/django/core/handlers/exception.py", line 34, in inner
    response = get_response(request)
  File "/opt/code/env/python/python3-django/venv/lib/python3.7/site-packages/django/core/handlers/base.py", line 126, in _get_response
    response = self.process_exception_by_middleware(e, request)
  File "/opt/code/env/python/python3-django/venv/lib/python3.7/site-packages/django/core/handlers/base.py", line 124, in _get_response
    response = wrapped_callback(request, *callback_args, **callback_kwargs)
  File "/opt/code/git/repository/devopsV2/mymessage/views.py", line 28, in index
    result=mymail(request,service)
  File "/opt/code/git/repository/devopsV2/mymessage/views.py", line 19, in mymail
    mails = MyThread(my_mail_send,requserid,reqmsg_title)
TypeError: __init__() takes 3 positional arguments but 4 were given
[2019-03-29 08:35:38,218][Thread-1:140417826928384][task_id:django.server][basehttp.py:136][ERROR]["POST /message/mail/ HTTP/1.1" 500 70760]
[2019-03-29 08:36:07,630][Thread-1:140387775309568][task_id:django.server][basehttp.py:136][INFO]["POST /message/mail/ HTTP/1.1" 200 31]
[2019-03-29 08:36:08,547][Thread-3:140387766916864][task_id:mymessage.myviews.Mail_Send][Mail_Send.py:14][INFO][1]
[2019-03-29 08:44:29,938][Thread-1:140081481602816][task_id:django.server][basehttp.py:136][INFO]["POST /message/mail/ HTTP/1.1" 200 31]
[2019-03-29 08:48:30,073][Thread-1:140145178953472][task_id:django.server][basehttp.py:136][INFO]["POST /message/mail/ HTTP/1.1" 200 31]
[2019-03-29 08:48:52,569][Thread-1:140585790912256][task_id:django.server][basehttp.py:136][INFO]["POST /message/mail/ HTTP/1.1" 200 31]
[2019-03-29 08:49:41,229][Thread-1:140665226884864][task_id:django.server][basehttp.py:136][INFO]["POST /message/mail/ HTTP/1.1" 200 31]
[2019-03-29 08:49:49,660][Thread-1:140665226884864][task_id:django.server][basehttp.py:136][INFO]["POST /message/mail/ HTTP/1.1" 200 31]
[2019-03-29 08:51:23,727][Thread-1:140683448112896][task_id:django.server][basehttp.py:136][INFO]["POST /message/mail/ HTTP/1.1" 200 31]
[2019-03-29 08:52:09,933][Thread-1:140131998246656][task_id:django.server][basehttp.py:136][INFO]["POST /message/mail/ HTTP/1.1" 200 31]
[2019-03-29 08:52:26,638][Thread-1:140131998246656][task_id:django.server][basehttp.py:136][INFO]["POST /message/mail/ HTTP/1.1" 200 31]
[2019-03-29 08:53:37,987][Thread-1:139643680978688][task_id:django.server][basehttp.py:136][INFO]["POST /message/mail/ HTTP/1.1" 200 31]
[2019-03-29 08:53:53,603][Thread-1:140323359553280][task_id:django.server][basehttp.py:136][INFO]["POST /message/mail/ HTTP/1.1" 200 31]
[2019-03-29 08:54:14,656][Thread-1:140480427517696][task_id:django.server][basehttp.py:136][INFO]["POST /message/mail/ HTTP/1.1" 200 31]
[2019-03-29 08:54:19,029][Thread-1:140480427517696][task_id:django.server][basehttp.py:136][INFO]["POST /message/mail/ HTTP/1.1" 200 31]
[2019-03-29 08:55:09,905][Thread-1:140299386267392][task_id:django.server][basehttp.py:136][INFO]["POST /message/mail/ HTTP/1.1" 200 31]
[2019-03-29 08:55:10,829][Thread-3:140299377874688][task_id:mymessage.myviews.Mail_Send][Mail_Send.py:16][INFO][1]
[2019-03-29 08:56:34,455][Thread-1:139750883813120][task_id:django.server][basehttp.py:136][INFO]["POST /message/mail/ HTTP/1.1" 200 31]
[2019-03-29 08:57:11,654][Thread-1:139967327299328][task_id:django.server][basehttp.py:136][INFO]["POST /message/mail/ HTTP/1.1" 200 31]
[2019-03-29 08:57:12,731][Thread-3:139967318906624][task_id:mymessage.myviews.Mail_Send][Mail_Send.py:17][INFO][1]
[2019-03-29 08:58:25,516][Thread-1:139967327299328][task_id:django.server][basehttp.py:136][INFO]["POST /message/mail/ HTTP/1.1" 200 31]
[2019-03-29 08:58:26,536][Thread-4:139967318906624][task_id:mymessage.myviews.Mail_Send][Mail_Send.py:17][INFO][1]
[2019-03-29 08:59:31,433][Thread-1:140290140665600][task_id:django.server][basehttp.py:136][INFO]["POST /message/mail/ HTTP/1.1" 200 31]
[2019-03-29 08:59:51,618][Thread-1:140290140665600][task_id:django.server][basehttp.py:136][INFO]["POST /message/mail/ HTTP/1.1" 200 31]
[2019-03-29 09:00:38,281][Thread-1:140608232232704][task_id:django.server][basehttp.py:136][INFO]["POST /message/mail/ HTTP/1.1" 200 31]
[2019-03-29 09:00:52,064][Thread-1:139945201104640][task_id:django.request][log.py:228][ERROR][Internal Server Error: /message/mail/]
Traceback (most recent call last):
  File "/opt/code/env/python/python3-django/venv/lib/python3.7/site-packages/django/core/handlers/exception.py", line 34, in inner
    response = get_response(request)
  File "/opt/code/env/python/python3-django/venv/lib/python3.7/site-packages/django/core/handlers/base.py", line 126, in _get_response
    response = self.process_exception_by_middleware(e, request)
  File "/opt/code/env/python/python3-django/venv/lib/python3.7/site-packages/django/core/handlers/base.py", line 124, in _get_response
    response = wrapped_callback(request, *callback_args, **callback_kwargs)
  File "/opt/code/git/repository/devopsV2/mymessage/views.py", line 28, in index
    result=mymail(request,service)
  File "/opt/code/git/repository/devopsV2/mymessage/views.py", line 19, in mymail
    mails = MyThread(my_mail_send,requserid=requserid,reqmsg_title=reqmsg_title,reqmsg_body=reqmsg_body)
NameError: name 'reqmsg_body' is not defined
[2019-03-29 09:00:52,065][Thread-1:139945201104640][task_id:django.server][basehttp.py:136][ERROR]["POST /message/mail/ HTTP/1.1" 500 70855]
[2019-03-29 09:01:03,958][Thread-1:139687613216512][task_id:django.request][log.py:228][ERROR][Internal Server Error: /message/mail/]
Traceback (most recent call last):
  File "/opt/code/env/python/python3-django/venv/lib/python3.7/site-packages/django/core/handlers/exception.py", line 34, in inner
    response = get_response(request)
  File "/opt/code/env/python/python3-django/venv/lib/python3.7/site-packages/django/core/handlers/base.py", line 126, in _get_response
    response = self.process_exception_by_middleware(e, request)
  File "/opt/code/env/python/python3-django/venv/lib/python3.7/site-packages/django/core/handlers/base.py", line 124, in _get_response
    response = wrapped_callback(request, *callback_args, **callback_kwargs)
  File "/opt/code/git/repository/devopsV2/mymessage/views.py", line 28, in index
    result=mymail(request,service)
  File "/opt/code/git/repository/devopsV2/mymessage/views.py", line 19, in mymail
    mails = MyThread(my_mail_send,requserid=requserid,reqmsg_title=reqmsg_title,reqmsg_body=reqmsg_body)
NameError: name 'reqmsg_body' is not defined
[2019-03-29 09:01:03,960][Thread-1:139687613216512][task_id:django.server][basehttp.py:136][ERROR]["POST /message/mail/ HTTP/1.1" 500 70855]
[2019-03-29 09:01:41,673][Thread-1:139979321628416][task_id:django.server][basehttp.py:136][INFO]["POST /message/mail/ HTTP/1.1" 200 31]
[2019-03-29 09:01:42,814][Thread-3:139979312973568][task_id:mymessage.myviews.Mail_Send][Mail_Send.py:18][INFO][1]
[2019-03-29 09:01:43,430][Thread-1:139979321628416][task_id:django.server][basehttp.py:136][INFO]["POST /message/mail/ HTTP/1.1" 200 31]
[2019-03-29 09:01:44,881][Thread-4:139979312973568][task_id:mymessage.myviews.Mail_Send][Mail_Send.py:18][INFO][1]
[2019-03-29 09:02:29,193][Thread-1:139979321628416][task_id:django.server][basehttp.py:136][INFO]["POST /message/mail/ HTTP/1.1" 200 31]
[2019-03-29 09:02:30,305][Thread-5:139979312973568][task_id:mymessage.myviews.Mail_Send][Mail_Send.py:18][INFO][1]
[2019-03-29 09:08:02,610][Thread-1:140410428065536][task_id:django.server][basehttp.py:136][INFO]["POST /message/mail/ HTTP/1.1" 200 31]
[2019-03-29 09:08:04,016][Thread-3:140410419410688][task_id:mymessage.myviews.Mail_Send][Mail_Send.py:18][INFO][1]
[2019-04-11 06:56:19,942][Thread-4:140410428065536][task_id:django.server][basehttp.py:136][INFO]["POST /message/mail/ HTTP/1.1" 200 31]
[2019-04-11 06:56:21,281][Thread-5:140410419410688][task_id:mymessage.myviews.Mail_Send][Mail_Send.py:18][INFO][1]
[2019-04-11 08:22:35,310][Thread-1:139630977672960][task_id:django.server][basehttp.py:136][INFO]["GET /consul/mysql-middleware2 HTTP/1.1" 200 1189]
[2019-04-11 08:22:35,560][Thread-1:139630977672960][task_id:django.request][log.py:228][WARNING][Not Found: /favicon.ico]
[2019-04-11 08:22:35,561][Thread-1:139630977672960][task_id:django.server][basehttp.py:136][WARNING]["GET /favicon.ico HTTP/1.1" 404 2313]
[2019-04-11 08:23:13,874][Thread-1:139630977672960][task_id:django.server][basehttp.py:136][INFO]["GET /consul/mysql-middleware2 HTTP/1.1" 200 1189]
[2019-04-11 09:25:37,250][Thread-1:139724089140992][task_id:django.server][basehttp.py:136][INFO]["GET /consul/index2 HTTP/1.1" 200 2]
[2019-04-11 09:26:05,171][Thread-1:140004488836864][task_id:django.server][basehttp.py:136][INFO]["GET /consul/index2 HTTP/1.1" 200 2]
[2019-04-11 09:26:06,134][Thread-1:140004488836864][task_id:django.server][basehttp.py:136][INFO]["GET /consul/index2 HTTP/1.1" 200 2]
[2019-04-12 09:02:48,012][Thread-1:140642044061440][task_id:django.server][basehttp.py:136][INFO]["GET /consul/index2 HTTP/1.1" 200 2]
[2019-04-12 09:02:48,316][Thread-1:140642044061440][task_id:django.request][log.py:228][WARNING][Not Found: /favicon.ico]
[2019-04-12 09:02:48,316][Thread-1:140642044061440][task_id:django.server][basehttp.py:136][WARNING]["GET /favicon.ico HTTP/1.1" 404 2313]
[2019-04-12 09:04:30,415][Thread-1:140642044061440][task_id:django.server][basehttp.py:136][INFO]["GET /consul/index2 HTTP/1.1" 200 2]
[2019-04-12 09:05:33,902][Thread-1:140010738726656][task_id:django.server][basehttp.py:136][INFO]["GET /consul/index2 HTTP/1.1" 200 2]
[2019-04-12 09:05:37,288][Thread-1:140010738726656][task_id:django.server][basehttp.py:136][INFO]["GET /consul/index2 HTTP/1.1" 200 2]
[2019-04-12 09:06:48,758][Thread-3:139690724292352][task_id:django.server][basehttp.py:136][INFO]["GET /consul/index2 HTTP/1.1" 200 2]
[2019-04-12 09:06:50,184][Thread-3:139690724292352][task_id:django.server][basehttp.py:136][INFO]["GET /consul/index2 HTTP/1.1" 200 2]
[2019-04-12 09:07:13,904][Thread-3:139896359327488][task_id:django.server][basehttp.py:136][INFO]["GET /consul/index2 HTTP/1.1" 200 2]
[2019-04-12 09:07:17,066][Thread-3:139896359327488][task_id:django.server][basehttp.py:136][INFO]["GET /consul/index2 HTTP/1.1" 200 2]
[2019-04-12 09:08:06,210][Thread-3:139687472768768][task_id:django.server][basehttp.py:136][INFO]["GET /consul/index2 HTTP/1.1" 200 2]
[2019-04-12 09:08:08,352][Thread-3:139687472768768][task_id:django.server][basehttp.py:136][INFO]["GET /consul/index2 HTTP/1.1" 200 2]
[2019-04-12 09:08:10,432][Thread-3:139687472768768][task_id:django.server][basehttp.py:136][INFO]["GET /consul/index2 HTTP/1.1" 200 2]
[2019-04-12 09:08:14,673][Thread-3:139687472768768][task_id:django.server][basehttp.py:136][INFO]["GET /consul/index2 HTTP/1.1" 200 2]
[2019-04-12 09:08:20,024][Thread-3:139687472768768][task_id:django.server][basehttp.py:136][INFO]["GET /consul/index2 HTTP/1.1" 200 2]
[2019-04-12 09:08:23,538][Thread-3:139687472768768][task_id:django.server][basehttp.py:136][INFO]["GET /consul/index2 HTTP/1.1" 200 2]
[2019-04-12 09:11:44,164][Thread-3:140085709920000][task_id:django.server][basehttp.py:136][INFO]["GET /consul/index2 HTTP/1.1" 200 2]
[2019-04-12 09:11:45,598][Thread-3:140085709920000][task_id:django.server][basehttp.py:136][INFO]["GET /consul/index2 HTTP/1.1" 200 2]
[2019-04-12 09:14:15,435][Thread-1:140502420285184][task_id:django.server][basehttp.py:136][INFO]["GET /consul/index2 HTTP/1.1" 200 2]
[2019-04-12 09:14:17,330][Thread-1:140502420285184][task_id:django.server][basehttp.py:136][INFO]["GET /consul/index2 HTTP/1.1" 200 2]
[2019-04-12 09:14:51,330][Thread-1:140536804853504][task_id:django.server][basehttp.py:136][INFO]["GET /consul/index2 HTTP/1.1" 200 2]
[2019-04-12 09:14:52,828][Thread-1:140536804853504][task_id:django.server][basehttp.py:136][INFO]["GET /consul/index2 HTTP/1.1" 200 2]
[2019-04-12 09:15:47,653][Thread-3:139758428743424][task_id:django.server][basehttp.py:136][INFO]["GET /consul/index2 HTTP/1.1" 200 2]
[2019-04-12 09:15:48,889][Thread-3:139758428743424][task_id:django.server][basehttp.py:136][INFO]["GET /consul/index2 HTTP/1.1" 200 2]
[2019-04-12 09:15:50,108][Thread-3:139758428743424][task_id:django.server][basehttp.py:136][INFO]["GET /consul/index2 HTTP/1.1" 200 2]
[2019-04-12 09:15:51,204][Thread-3:139758428743424][task_id:django.server][basehttp.py:136][INFO]["GET /consul/index2 HTTP/1.1" 200 2]
[2019-04-12 09:15:52,116][Thread-3:139758428743424][task_id:django.server][basehttp.py:136][INFO]["GET /consul/index2 HTTP/1.1" 200 2]
[2019-04-12 09:16:26,075][Thread-3:139915765786368][task_id:django.server][basehttp.py:136][INFO]["GET /consul/index2 HTTP/1.1" 200 2]
[2019-04-12 09:16:27,054][Thread-3:139915765786368][task_id:django.server][basehttp.py:136][INFO]["GET /consul/index2 HTTP/1.1" 200 2]
[2019-04-12 09:17:28,152][Thread-3:140367017125632][task_id:django.server][basehttp.py:136][INFO]["GET /consul/index2 HTTP/1.1" 200 12]
[2019-04-12 09:17:29,251][Thread-3:140367017125632][task_id:django.server][basehttp.py:136][INFO]["GET /consul/index2 HTTP/1.1" 200 12]
[2019-04-12 09:17:34,515][Thread-3:140367017125632][task_id:django.server][basehttp.py:136][INFO]["GET /consul/mysql-middleware2 HTTP/1.1" 200 1189]
[2019-04-12 09:17:37,900][Thread-3:140367017125632][task_id:django.server][basehttp.py:136][INFO]["GET /consul/index2 HTTP/1.1" 200 12]
[2019-04-12 09:28:32,959][Thread-1:140348606236416][task_id:django.server][basehttp.py:136][INFO]["GET /consul/index2 HTTP/1.1" 200 12]
[2019-04-12 09:28:33,847][Thread-1:140348606236416][task_id:django.server][basehttp.py:136][INFO]["GET /consul/index2 HTTP/1.1" 200 12]
[2019-04-19 07:04:50,372][Thread-1:140061711628032][task_id:django.server][basehttp.py:136][INFO]["POST /message/mail/ HTTP/1.1" 200 31]
[2019-04-19 07:19:08,569][Thread-4:140061634983680][task_id:django.server][basehttp.py:136][INFO]["GET /consul/index2 HTTP/1.1" 200 12]
[2019-04-19 07:19:08,831][Thread-4:140061634983680][task_id:django.request][log.py:228][WARNING][Not Found: /favicon.ico]
[2019-04-19 07:19:08,831][Thread-4:140061634983680][task_id:django.server][basehttp.py:136][WARNING]["GET /favicon.ico HTTP/1.1" 404 2313]
[2019-04-19 08:18:24,922][Thread-7:140061626590976][task_id:django.server][basehttp.py:136][INFO]["GET /consul/index2 HTTP/1.1" 200 12]
[2019-04-19 09:25:08,908][Thread-1:140582289884928][task_id:django.server][basehttp.py:136][INFO]["GET /consul/index2 HTTP/1.1" 200 12]
[2019-04-19 09:25:10,771][Thread-1:140582289884928][task_id:django.server][basehttp.py:136][INFO]["GET /consul/index2 HTTP/1.1" 200 12]
[2019-04-22 06:17:23,255][Thread-1:139849542190848][task_id:django.server][basehttp.py:136][INFO]["GET /consul/index2 HTTP/1.1" 200 12]
[2019-04-22 06:17:23,493][Thread-1:139849542190848][task_id:django.request][log.py:228][WARNING][Not Found: /favicon.ico]
[2019-04-22 06:17:23,494][Thread-1:139849542190848][task_id:django.server][basehttp.py:136][WARNING]["GET /favicon.ico HTTP/1.1" 404 2313]
[2019-04-22 06:17:54,232][Thread-1:140186231551744][task_id:django.server][basehttp.py:136][INFO]["GET /consul/index2 HTTP/1.1" 200 316]
[2019-04-22 06:19:43,696][Thread-1:140439148926720][task_id:django.server][basehttp.py:136][INFO]["GET /consul/index2 HTTP/1.1" 200 2]
[2019-04-22 06:19:49,717][Thread-1:140439148926720][task_id:django.server][basehttp.py:136][INFO]["GET /consul/remotehttp HTTP/1.1" 200 316]
[2019-04-22 06:21:27,523][Thread-1:140439148926720][task_id:django.server][basehttp.py:136][INFO]["GET /consul/remotehttp HTTP/1.1" 200 316]
[2019-04-22 06:39:14,003][Thread-5:140439148926720][task_id:django.server][basehttp.py:136][INFO]["GET /consul/remotehttp HTTP/1.1" 200 316]
[2019-04-22 06:47:19,007][Thread-1:140090132772608][task_id:django.request][log.py:228][ERROR][Internal Server Error: /consul/remotehttp]
Traceback (most recent call last):
  File "/opt/code/env/python/python3-django/venv/lib/python3.7/site-packages/django/core/handlers/exception.py", line 34, in inner
    response = get_response(request)
  File "/opt/code/env/python/python3-django/venv/lib/python3.7/site-packages/django/core/handlers/base.py", line 126, in _get_response
    response = self.process_exception_by_middleware(e, request)
  File "/opt/code/env/python/python3-django/venv/lib/python3.7/site-packages/django/core/handlers/base.py", line 124, in _get_response
    response = wrapped_callback(request, *callback_args, **callback_kwargs)
  File "/opt/code/git/repository/devopsV2/myhttp/myviews/views.py", line 37, in remotehttp
    return(HttpResponse(redate.decode('utf-8')))
AttributeError: 'dict' object has no attribute 'decode'
[2019-04-22 06:47:19,009][Thread-1:140090132772608][task_id:django.server][basehttp.py:136][ERROR]["GET /consul/remotehttp HTTP/1.1" 500 67233]
[2019-04-22 06:47:55,550][Thread-1:139676318480128][task_id:django.request][log.py:228][ERROR][Internal Server Error: /consul/remotehttp]
Traceback (most recent call last):
  File "/opt/code/env/python/python3-django/venv/lib/python3.7/site-packages/django/core/handlers/exception.py", line 34, in inner
    response = get_response(request)
  File "/opt/code/env/python/python3-django/venv/lib/python3.7/site-packages/django/core/handlers/base.py", line 126, in _get_response
    response = self.process_exception_by_middleware(e, request)
  File "/opt/code/env/python/python3-django/venv/lib/python3.7/site-packages/django/core/handlers/base.py", line 124, in _get_response
    response = wrapped_callback(request, *callback_args, **callback_kwargs)
  File "/opt/code/git/repository/devopsV2/myhttp/myviews/views.py", line 37, in remotehttp
    return(HttpResponse(redate.decode('utf-8')))
AttributeError: 'dict' object has no attribute 'decode'
[2019-04-22 06:47:55,551][Thread-1:139676318480128][task_id:django.server][basehttp.py:136][ERROR]["GET /consul/remotehttp HTTP/1.1" 500 67233]
[2019-04-22 06:50:28,311][Thread-3:140033882371840][task_id:django.request][log.py:228][ERROR][Internal Server Error: /consul/remotehttp]
Traceback (most recent call last):
  File "/opt/code/env/python/python3-django/venv/lib/python3.7/site-packages/django/core/handlers/exception.py", line 34, in inner
    response = get_response(request)
  File "/opt/code/env/python/python3-django/venv/lib/python3.7/site-packages/django/core/handlers/base.py", line 126, in _get_response
    response = self.process_exception_by_middleware(e, request)
  File "/opt/code/env/python/python3-django/venv/lib/python3.7/site-packages/django/core/handlers/base.py", line 124, in _get_response
    response = wrapped_callback(request, *callback_args, **callback_kwargs)
  File "/opt/code/git/repository/devopsV2/myhttp/myviews/views.py", line 37, in remotehttp
    return(HttpResponse(redate.decode('utf-8')))
AttributeError: 'dict' object has no attribute 'decode'
[2019-04-22 06:50:28,312][Thread-3:140033882371840][task_id:django.server][basehttp.py:136][ERROR]["GET /consul/remotehttp HTTP/1.1" 500 67233]
[2019-04-22 06:52:56,328][Thread-3:140627195242240][task_id:django.request][log.py:228][ERROR][Internal Server Error: /consul/remotehttp]
Traceback (most recent call last):
  File "/opt/code/env/python/python3-django/venv/lib/python3.7/site-packages/django/core/handlers/exception.py", line 34, in inner
    response = get_response(request)
  File "/opt/code/env/python/python3-django/venv/lib/python3.7/site-packages/django/core/handlers/base.py", line 126, in _get_response
    response = self.process_exception_by_middleware(e, request)
  File "/opt/code/env/python/python3-django/venv/lib/python3.7/site-packages/django/core/handlers/base.py", line 124, in _get_response
    response = wrapped_callback(request, *callback_args, **callback_kwargs)
  File "/opt/code/git/repository/devopsV2/myhttp/myviews/views.py", line 37, in remotehttp
    return(HttpResponse(redate.decode('utf-8')))
AttributeError: 'HttpResponse' object has no attribute 'decode'
[2019-04-22 06:52:56,329][Thread-3:140627195242240][task_id:django.server][basehttp.py:136][ERROR]["GET /consul/remotehttp HTTP/1.1" 500 66854]
[2019-04-22 06:53:00,062][Thread-3:140627195242240][task_id:django.request][log.py:228][ERROR][Internal Server Error: /consul/remotehttp]
Traceback (most recent call last):
  File "/opt/code/env/python/python3-django/venv/lib/python3.7/site-packages/django/core/handlers/exception.py", line 34, in inner
    response = get_response(request)
  File "/opt/code/env/python/python3-django/venv/lib/python3.7/site-packages/django/core/handlers/base.py", line 126, in _get_response
    response = self.process_exception_by_middleware(e, request)
  File "/opt/code/env/python/python3-django/venv/lib/python3.7/site-packages/django/core/handlers/base.py", line 124, in _get_response
    response = wrapped_callback(request, *callback_args, **callback_kwargs)
  File "/opt/code/git/repository/devopsV2/myhttp/myviews/views.py", line 37, in remotehttp
    return(HttpResponse(redate.decode('utf-8')))
AttributeError: 'HttpResponse' object has no attribute 'decode'
[2019-04-22 06:53:00,063][Thread-3:140627195242240][task_id:django.server][basehttp.py:136][ERROR]["GET /consul/remotehttp HTTP/1.1" 500 66854]
[2019-04-22 06:53:03,120][Thread-3:140627195242240][task_id:django.request][log.py:228][ERROR][Internal Server Error: /consul/remotehttp]
Traceback (most recent call last):
  File "/opt/code/env/python/python3-django/venv/lib/python3.7/site-packages/django/core/handlers/exception.py", line 34, in inner
    response = get_response(request)
  File "/opt/code/env/python/python3-django/venv/lib/python3.7/site-packages/django/core/handlers/base.py", line 126, in _get_response
    response = self.process_exception_by_middleware(e, request)
  File "/opt/code/env/python/python3-django/venv/lib/python3.7/site-packages/django/core/handlers/base.py", line 124, in _get_response
    response = wrapped_callback(request, *callback_args, **callback_kwargs)
  File "/opt/code/git/repository/devopsV2/myhttp/myviews/views.py", line 37, in remotehttp
    return(HttpResponse(redate.decode('utf-8')))
AttributeError: 'HttpResponse' object has no attribute 'decode'
[2019-04-22 06:53:03,121][Thread-3:140627195242240][task_id:django.server][basehttp.py:136][ERROR]["GET /consul/remotehttp HTTP/1.1" 500 66854]
[2019-04-22 06:53:55,341][Thread-3:140493792253696][task_id:django.request][log.py:228][ERROR][Internal Server Error: /consul/remotehttp]
Traceback (most recent call last):
  File "/opt/code/env/python/python3-django/venv/lib/python3.7/site-packages/django/core/handlers/exception.py", line 34, in inner
    response = get_response(request)
  File "/opt/code/env/python/python3-django/venv/lib/python3.7/site-packages/django/core/handlers/base.py", line 126, in _get_response
    response = self.process_exception_by_middleware(e, request)
  File "/opt/code/env/python/python3-django/venv/lib/python3.7/site-packages/django/core/handlers/base.py", line 124, in _get_response
    response = wrapped_callback(request, *callback_args, **callback_kwargs)
  File "/opt/code/git/repository/devopsV2/myhttp/myviews/views.py", line 36, in remotehttp
    redate = data.http_get()
  File "/opt/code/git/repository/devopsV2/myhttp/myviews/viewmyhttp.py", line 33, in http_get
    return(HttpResponse(myresponse).decode('utf-8'))
AttributeError: 'HttpResponse' object has no attribute 'decode'
[2019-04-22 06:53:55,342][Thread-3:140493792253696][task_id:django.server][basehttp.py:136][ERROR]["GET /consul/remotehttp HTTP/1.1" 500 71688]
[2019-04-22 06:54:52,906][Thread-1:140534819583744][task_id:django.request][log.py:228][ERROR][Internal Server Error: /consul/remotehttp]
Traceback (most recent call last):
  File "/opt/code/env/python/python3-django/venv/lib/python3.7/site-packages/django/core/handlers/exception.py", line 34, in inner
    response = get_response(request)
  File "/opt/code/env/python/python3-django/venv/lib/python3.7/site-packages/django/core/handlers/base.py", line 126, in _get_response
    response = self.process_exception_by_middleware(e, request)
  File "/opt/code/env/python/python3-django/venv/lib/python3.7/site-packages/django/core/handlers/base.py", line 124, in _get_response
    response = wrapped_callback(request, *callback_args, **callback_kwargs)
  File "/opt/code/git/repository/devopsV2/myhttp/myviews/views.py", line 37, in remotehttp
    return(HttpResponse(redate.decode('utf-8')))
AttributeError: 'HttpResponse' object has no attribute 'decode'
[2019-04-22 06:54:52,908][Thread-1:140534819583744][task_id:django.server][basehttp.py:136][ERROR]["GET /consul/remotehttp HTTP/1.1" 500 66854]
[2019-04-22 06:55:11,971][Thread-1:140440963667712][task_id:django.request][log.py:228][ERROR][Internal Server Error: /consul/remotehttp]
Traceback (most recent call last):
  File "/opt/code/env/python/python3-django/venv/lib/python3.7/site-packages/django/core/handlers/exception.py", line 34, in inner
    response = get_response(request)
  File "/opt/code/env/python/python3-django/venv/lib/python3.7/site-packages/django/core/handlers/base.py", line 126, in _get_response
    response = self.process_exception_by_middleware(e, request)
  File "/opt/code/env/python/python3-django/venv/lib/python3.7/site-packages/django/core/handlers/base.py", line 124, in _get_response
    response = wrapped_callback(request, *callback_args, **callback_kwargs)
  File "/opt/code/git/repository/devopsV2/myhttp/myviews/views.py", line 37, in remotehttp
    return(HttpResponse(redate.decode('utf-8')))
AttributeError: 'str' object has no attribute 'decode'
[2019-04-22 06:55:11,972][Thread-1:140440963667712][task_id:django.server][basehttp.py:136][ERROR]["GET /consul/remotehttp HTTP/1.1" 500 67322]
[2019-04-22 06:55:14,451][Thread-1:140440963667712][task_id:django.request][log.py:228][ERROR][Internal Server Error: /consul/remotehttp]
Traceback (most recent call last):
  File "/opt/code/env/python/python3-django/venv/lib/python3.7/site-packages/django/core/handlers/exception.py", line 34, in inner
    response = get_response(request)
  File "/opt/code/env/python/python3-django/venv/lib/python3.7/site-packages/django/core/handlers/base.py", line 126, in _get_response
    response = self.process_exception_by_middleware(e, request)
  File "/opt/code/env/python/python3-django/venv/lib/python3.7/site-packages/django/core/handlers/base.py", line 124, in _get_response
    response = wrapped_callback(request, *callback_args, **callback_kwargs)
  File "/opt/code/git/repository/devopsV2/myhttp/myviews/views.py", line 37, in remotehttp
    return(HttpResponse(redate.decode('utf-8')))
AttributeError: 'str' object has no attribute 'decode'
[2019-04-22 06:55:14,452][Thread-1:140440963667712][task_id:django.server][basehttp.py:136][ERROR]["GET /consul/remotehttp HTTP/1.1" 500 67322]
[2019-04-22 06:56:23,054][Thread-1:140452794947328][task_id:django.request][log.py:228][ERROR][Internal Server Error: /consul/remotehttp]
Traceback (most recent call last):
  File "/opt/code/env/python/python3-django/venv/lib/python3.7/site-packages/django/core/handlers/exception.py", line 34, in inner
    response = get_response(request)
  File "/opt/code/env/python/python3-django/venv/lib/python3.7/site-packages/django/core/handlers/base.py", line 126, in _get_response
    response = self.process_exception_by_middleware(e, request)
  File "/opt/code/env/python/python3-django/venv/lib/python3.7/site-packages/django/core/handlers/base.py", line 124, in _get_response
    response = wrapped_callback(request, *callback_args, **callback_kwargs)
  File "/opt/code/git/repository/devopsV2/myhttp/myviews/views.py", line 37, in remotehttp
    return(HttpResponse(redate.decode('utf-8')))
AttributeError: 'str' object has no attribute 'decode'
[2019-04-22 06:56:23,055][Thread-1:140452794947328][task_id:django.server][basehttp.py:136][ERROR]["GET /consul/remotehttp HTTP/1.1" 500 67322]
[2019-04-22 06:56:34,977][Thread-1:140452794947328][task_id:django.request][log.py:228][ERROR][Internal Server Error: /consul/remotehttp]
Traceback (most recent call last):
  File "/opt/code/env/python/python3-django/venv/lib/python3.7/site-packages/django/core/handlers/exception.py", line 34, in inner
    response = get_response(request)
  File "/opt/code/env/python/python3-django/venv/lib/python3.7/site-packages/django/core/handlers/base.py", line 126, in _get_response
    response = self.process_exception_by_middleware(e, request)
  File "/opt/code/env/python/python3-django/venv/lib/python3.7/site-packages/django/core/handlers/base.py", line 124, in _get_response
    response = wrapped_callback(request, *callback_args, **callback_kwargs)
  File "/opt/code/git/repository/devopsV2/myhttp/myviews/views.py", line 37, in remotehttp
    return(HttpResponse(redate.decode('utf-8')))
AttributeError: 'str' object has no attribute 'decode'
[2019-04-22 06:56:34,978][Thread-1:140452794947328][task_id:django.server][basehttp.py:136][ERROR]["GET /consul/remotehttp HTTP/1.1" 500 67322]
[2019-04-22 06:59:32,905][Thread-1:140452794947328][task_id:django.request][log.py:228][ERROR][Internal Server Error: /consul/remotehttp]
Traceback (most recent call last):
  File "/opt/code/env/python/python3-django/venv/lib/python3.7/site-packages/django/core/handlers/exception.py", line 34, in inner
    response = get_response(request)
  File "/opt/code/env/python/python3-django/venv/lib/python3.7/site-packages/django/core/handlers/base.py", line 126, in _get_response
    response = self.process_exception_by_middleware(e, request)
  File "/opt/code/env/python/python3-django/venv/lib/python3.7/site-packages/django/core/handlers/base.py", line 124, in _get_response
    response = wrapped_callback(request, *callback_args, **callback_kwargs)
  File "/opt/code/git/repository/devopsV2/myhttp/myviews/views.py", line 37, in remotehttp
    return(HttpResponse(redate.decode('utf-8')))
AttributeError: 'str' object has no attribute 'decode'
[2019-04-22 06:59:32,905][Thread-1:140452794947328][task_id:django.server][basehttp.py:136][ERROR]["GET /consul/remotehttp HTTP/1.1" 500 67322]
[2019-04-22 07:00:04,229][Thread-3:139979391543040][task_id:django.server][basehttp.py:136][INFO]["GET /consul/remotehttp HTTP/1.1" 200 316]
[2019-04-22 07:00:50,612][Thread-3:140628671112960][task_id:django.server][basehttp.py:136][INFO]["GET /consul/remotehttp HTTP/1.1" 200 316]
[2019-04-22 07:03:30,232][Thread-3:140346951575296][task_id:django.request][log.py:228][ERROR][Internal Server Error: /consul/remotehttp]
Traceback (most recent call last):
  File "/opt/code/env/python/python3-django/venv/lib/python3.7/site-packages/django/core/handlers/exception.py", line 34, in inner
    response = get_response(request)
  File "/opt/code/env/python/python3-django/venv/lib/python3.7/site-packages/django/core/handlers/base.py", line 126, in _get_response
    response = self.process_exception_by_middleware(e, request)
  File "/opt/code/env/python/python3-django/venv/lib/python3.7/site-packages/django/core/handlers/base.py", line 124, in _get_response
    response = wrapped_callback(request, *callback_args, **callback_kwargs)
  File "/opt/code/git/repository/devopsV2/myhttp/myviews/views.py", line 37, in remotehttp
    return(HttpResponse(redate.decode('utf-8')))
AttributeError: 'HttpResponse' object has no attribute 'decode'
[2019-04-22 07:03:30,234][Thread-3:140346951575296][task_id:django.server][basehttp.py:136][ERROR]["GET /consul/remotehttp HTTP/1.1" 500 66854]
[2019-04-22 07:13:55,785][Thread-1:140090290468608][task_id:django.server][basehttp.py:136][INFO]["GET /consul/remotehttp HTTP/1.1" 200 316]
[2019-04-22 07:15:13,105][Thread-1:140224315291392][task_id:django.request][log.py:228][ERROR][Internal Server Error: /consul/remotehttp]
Traceback (most recent call last):
  File "/opt/code/env/python/python3-django/venv/lib/python3.7/site-packages/django/core/handlers/exception.py", line 34, in inner
    response = get_response(request)
  File "/opt/code/env/python/python3-django/venv/lib/python3.7/site-packages/django/core/handlers/base.py", line 126, in _get_response
    response = self.process_exception_by_middleware(e, request)
  File "/opt/code/env/python/python3-django/venv/lib/python3.7/site-packages/django/core/handlers/base.py", line 124, in _get_response
    response = wrapped_callback(request, *callback_args, **callback_kwargs)
  File "/opt/code/git/repository/devopsV2/myhttp/myviews/views.py", line 36, in remotehttp
    redate = data.http_get()
  File "/opt/code/git/repository/devopsV2/myhttp/myviews/viewmyhttp.py", line 31, in http_get
    print(myresponse.decode('utf-8'))
AttributeError: 'str' object has no attribute 'decode'
[2019-04-22 07:15:13,108][Thread-1:140224315291392][task_id:django.server][basehttp.py:136][ERROR]["GET /consul/remotehttp HTTP/1.1" 500 71717]
[2019-04-22 07:15:18,906][Thread-1:139922113402624][task_id:django.server][basehttp.py:136][INFO]["GET /consul/remotehttp HTTP/1.1" 200 316]
[2019-04-22 07:18:01,440][Thread-1:140145923716864][task_id:django.request][log.py:228][ERROR][Internal Server Error: /consul/remotehttp]
Traceback (most recent call last):
  File "/opt/code/env/python/python3-django/venv/lib/python3.7/site-packages/django/core/handlers/exception.py", line 34, in inner
    response = get_response(request)
  File "/opt/code/env/python/python3-django/venv/lib/python3.7/site-packages/django/core/handlers/base.py", line 126, in _get_response
    response = self.process_exception_by_middleware(e, request)
  File "/opt/code/env/python/python3-django/venv/lib/python3.7/site-packages/django/core/handlers/base.py", line 124, in _get_response
    response = wrapped_callback(request, *callback_args, **callback_kwargs)
  File "/opt/code/git/repository/devopsV2/myhttp/myviews/views.py", line 37, in remotehttp
    return(HttpResponse(redate.decode('utf-8')))
AttributeError: 'dict' object has no attribute 'decode'
[2019-04-22 07:18:01,442][Thread-1:140145923716864][task_id:django.server][basehttp.py:136][ERROR]["GET /consul/remotehttp HTTP/1.1" 500 67233]
[2019-04-22 07:18:30,743][Thread-1:140483703879424][task_id:django.request][log.py:228][ERROR][Internal Server Error: /consul/remotehttp]
Traceback (most recent call last):
  File "/opt/code/env/python/python3-django/venv/lib/python3.7/site-packages/django/core/handlers/exception.py", line 34, in inner
    response = get_response(request)
  File "/opt/code/env/python/python3-django/venv/lib/python3.7/site-packages/django/core/handlers/base.py", line 126, in _get_response
    response = self.process_exception_by_middleware(e, request)
  File "/opt/code/env/python/python3-django/venv/lib/python3.7/site-packages/django/core/handlers/base.py", line 124, in _get_response
    response = wrapped_callback(request, *callback_args, **callback_kwargs)
  File "/opt/code/git/repository/devopsV2/myhttp/myviews/views.py", line 37, in remotehttp
    return(HttpResponse(redate.decode('utf-8')))
AttributeError: 'dict' object has no attribute 'decode'
[2019-04-22 07:18:30,744][Thread-1:140483703879424][task_id:django.server][basehttp.py:136][ERROR]["GET /consul/remotehttp HTTP/1.1" 500 67233]
[2019-04-22 07:25:08,679][Thread-3:140614410696448][task_id:django.request][log.py:228][ERROR][Internal Server Error: /consul/remotehttp]
Traceback (most recent call last):
  File "/opt/code/env/python/python3-django/venv/lib/python3.7/site-packages/django/core/handlers/exception.py", line 34, in inner
    response = get_response(request)
  File "/opt/code/env/python/python3-django/venv/lib/python3.7/site-packages/django/core/handlers/base.py", line 126, in _get_response
    response = self.process_exception_by_middleware(e, request)
  File "/opt/code/env/python/python3-django/venv/lib/python3.7/site-packages/django/core/handlers/base.py", line 124, in _get_response
    response = wrapped_callback(request, *callback_args, **callback_kwargs)
  File "/opt/code/git/repository/devopsV2/myhttp/myviews/views.py", line 37, in remotehttp
    return(HttpResponse(redate.decode('utf-8')))
AttributeError: 'JsonResponse' object has no attribute 'decode'
[2019-04-22 07:25:08,680][Thread-3:140614410696448][task_id:django.server][basehttp.py:136][ERROR]["GET /consul/remotehttp HTTP/1.1" 500 66846]
[2019-04-22 07:27:43,053][Thread-1:140667383289600][task_id:django.request][log.py:228][ERROR][Internal Server Error: /consul/remotehttp]
Traceback (most recent call last):
  File "/opt/code/env/python/python3-django/venv/lib/python3.7/site-packages/django/core/handlers/exception.py", line 34, in inner
    response = get_response(request)
  File "/opt/code/env/python/python3-django/venv/lib/python3.7/site-packages/django/core/handlers/base.py", line 126, in _get_response
    response = self.process_exception_by_middleware(e, request)
  File "/opt/code/env/python/python3-django/venv/lib/python3.7/site-packages/django/core/handlers/base.py", line 124, in _get_response
    response = wrapped_callback(request, *callback_args, **callback_kwargs)
  File "/opt/code/git/repository/devopsV2/myhttp/myviews/views.py", line 37, in remotehttp
    return(HttpResponse(redate.decode('utf-8')))
AttributeError: 'JsonResponse' object has no attribute 'decode'
[2019-04-22 07:27:43,054][Thread-1:140667383289600][task_id:django.server][basehttp.py:136][ERROR]["GET /consul/remotehttp HTTP/1.1" 500 66846]
[2019-04-22 07:29:15,785][Thread-1:140172524037888][task_id:root][viewmyhttp.py:38][ERROR][name 'response' is not defined]
[2019-04-22 07:29:15,825][Thread-1:140172524037888][task_id:django.request][log.py:228][ERROR][Internal Server Error: /consul/remotehttp]
Traceback (most recent call last):
  File "/opt/code/env/python/python3-django/venv/lib/python3.7/site-packages/django/core/handlers/exception.py", line 34, in inner
    response = get_response(request)
  File "/opt/code/env/python/python3-django/venv/lib/python3.7/site-packages/django/core/handlers/base.py", line 126, in _get_response
    response = self.process_exception_by_middleware(e, request)
  File "/opt/code/env/python/python3-django/venv/lib/python3.7/site-packages/django/core/handlers/base.py", line 124, in _get_response
    response = wrapped_callback(request, *callback_args, **callback_kwargs)
  File "/opt/code/git/repository/devopsV2/myhttp/myviews/views.py", line 37, in remotehttp
    return(HttpResponse(redate.decode('utf-8')))
AttributeError: 'JsonResponse' object has no attribute 'decode'
[2019-04-22 07:29:15,826][Thread-1:140172524037888][task_id:django.server][basehttp.py:136][ERROR]["GET /consul/remotehttp HTTP/1.1" 500 66846]
[2019-04-22 07:29:34,669][Thread-3:140460693174016][task_id:django.request][log.py:228][ERROR][Internal Server Error: /consul/remotehttp]
Traceback (most recent call last):
  File "/opt/code/env/python/python3-django/venv/lib/python3.7/site-packages/django/core/handlers/exception.py", line 34, in inner
    response = get_response(request)
  File "/opt/code/env/python/python3-django/venv/lib/python3.7/site-packages/django/core/handlers/base.py", line 126, in _get_response
    response = self.process_exception_by_middleware(e, request)
  File "/opt/code/env/python/python3-django/venv/lib/python3.7/site-packages/django/core/handlers/base.py", line 124, in _get_response
    response = wrapped_callback(request, *callback_args, **callback_kwargs)
  File "/opt/code/git/repository/devopsV2/myhttp/myviews/views.py", line 37, in remotehttp
    return(HttpResponse(redate.decode('utf-8')))
AttributeError: 'JsonResponse' object has no attribute 'decode'
[2019-04-22 07:29:34,671][Thread-3:140460693174016][task_id:django.server][basehttp.py:136][ERROR]["GET /consul/remotehttp HTTP/1.1" 500 66846]
[2019-04-22 07:32:35,808][Thread-1:139910995130112][task_id:django.request][log.py:228][ERROR][Internal Server Error: /consul/remotehttp]
Traceback (most recent call last):
  File "/opt/code/env/python/python3-django/venv/lib/python3.7/site-packages/django/core/handlers/exception.py", line 34, in inner
    response = get_response(request)
  File "/opt/code/env/python/python3-django/venv/lib/python3.7/site-packages/django/core/handlers/base.py", line 126, in _get_response
    response = self.process_exception_by_middleware(e, request)
  File "/opt/code/env/python/python3-django/venv/lib/python3.7/site-packages/django/core/handlers/base.py", line 124, in _get_response
    response = wrapped_callback(request, *callback_args, **callback_kwargs)
  File "/opt/code/git/repository/devopsV2/myhttp/myviews/views.py", line 37, in remotehttp
    return(HttpResponse(redate.decode('utf-8')))
AttributeError: 'JsonResponse' object has no attribute 'decode'
[2019-04-22 07:32:35,809][Thread-1:139910995130112][task_id:django.server][basehttp.py:136][ERROR]["GET /consul/remotehttp HTTP/1.1" 500 66846]
[2019-04-22 07:33:15,493][Thread-1:140558606087936][task_id:django.request][log.py:228][ERROR][Internal Server Error: /consul/remotehttp]
Traceback (most recent call last):
  File "/opt/code/env/python/python3-django/venv/lib/python3.7/site-packages/django/core/handlers/exception.py", line 34, in inner
    response = get_response(request)
  File "/opt/code/env/python/python3-django/venv/lib/python3.7/site-packages/django/core/handlers/base.py", line 126, in _get_response
    response = self.process_exception_by_middleware(e, request)
  File "/opt/code/env/python/python3-django/venv/lib/python3.7/site-packages/django/core/handlers/base.py", line 124, in _get_response
    response = wrapped_callback(request, *callback_args, **callback_kwargs)
  File "/opt/code/git/repository/devopsV2/myhttp/myviews/views.py", line 37, in remotehttp
    return(HttpResponse(redate.decode('utf-8')))
AttributeError: 'JsonResponse' object has no attribute 'decode'
[2019-04-22 07:33:15,495][Thread-1:140558606087936][task_id:django.server][basehttp.py:136][ERROR]["GET /consul/remotehttp HTTP/1.1" 500 66846]
[2019-04-22 07:33:32,149][Thread-3:139695386044160][task_id:django.request][log.py:228][ERROR][Internal Server Error: /consul/remotehttp]
Traceback (most recent call last):
  File "/opt/code/env/python/python3-django/venv/lib/python3.7/site-packages/django/core/handlers/exception.py", line 34, in inner
    response = get_response(request)
  File "/opt/code/env/python/python3-django/venv/lib/python3.7/site-packages/django/core/handlers/base.py", line 126, in _get_response
    response = self.process_exception_by_middleware(e, request)
  File "/opt/code/env/python/python3-django/venv/lib/python3.7/site-packages/django/core/handlers/base.py", line 124, in _get_response
    response = wrapped_callback(request, *callback_args, **callback_kwargs)
  File "/opt/code/git/repository/devopsV2/myhttp/myviews/views.py", line 37, in remotehttp
    return(HttpResponse(redate.decode('utf-8')))
AttributeError: 'JsonResponse' object has no attribute 'decode'
[2019-04-22 07:33:32,150][Thread-3:139695386044160][task_id:django.server][basehttp.py:136][ERROR]["GET /consul/remotehttp HTTP/1.1" 500 66846]
[2019-04-22 07:33:35,753][Thread-3:139695386044160][task_id:django.request][log.py:228][ERROR][Internal Server Error: /consul/remotehttp]
Traceback (most recent call last):
  File "/opt/code/env/python/python3-django/venv/lib/python3.7/site-packages/django/core/handlers/exception.py", line 34, in inner
    response = get_response(request)
  File "/opt/code/env/python/python3-django/venv/lib/python3.7/site-packages/django/core/handlers/base.py", line 126, in _get_response
    response = self.process_exception_by_middleware(e, request)
  File "/opt/code/env/python/python3-django/venv/lib/python3.7/site-packages/django/core/handlers/base.py", line 124, in _get_response
    response = wrapped_callback(request, *callback_args, **callback_kwargs)
  File "/opt/code/git/repository/devopsV2/myhttp/myviews/views.py", line 37, in remotehttp
    return(HttpResponse(redate.decode('utf-8')))
AttributeError: 'JsonResponse' object has no attribute 'decode'
[2019-04-22 07:33:35,754][Thread-3:139695386044160][task_id:django.server][basehttp.py:136][ERROR]["GET /consul/remotehttp HTTP/1.1" 500 66846]
[2019-04-22 07:33:51,202][Thread-1:140205851932416][task_id:root][viewmyhttp.py:38][ERROR]['dict' object has no attribute 'content']
[2019-04-22 07:33:51,240][Thread-1:140205851932416][task_id:django.request][log.py:228][ERROR][Internal Server Error: /consul/remotehttp]
Traceback (most recent call last):
  File "/opt/code/env/python/python3-django/venv/lib/python3.7/site-packages/django/core/handlers/exception.py", line 34, in inner
    response = get_response(request)
  File "/opt/code/env/python/python3-django/venv/lib/python3.7/site-packages/django/core/handlers/base.py", line 126, in _get_response
    response = self.process_exception_by_middleware(e, request)
  File "/opt/code/env/python/python3-django/venv/lib/python3.7/site-packages/django/core/handlers/base.py", line 124, in _get_response
    response = wrapped_callback(request, *callback_args, **callback_kwargs)
  File "/opt/code/git/repository/devopsV2/myhttp/myviews/views.py", line 37, in remotehttp
    return(HttpResponse(redate.decode('utf-8')))
AttributeError: 'dict' object has no attribute 'decode'
[2019-04-22 07:33:51,242][Thread-1:140205851932416][task_id:django.server][basehttp.py:136][ERROR]["GET /consul/remotehttp HTTP/1.1" 500 67233]
[2019-04-22 07:33:54,703][Thread-1:140205851932416][task_id:root][viewmyhttp.py:38][ERROR]['dict' object has no attribute 'content']
[2019-04-22 07:33:54,742][Thread-1:140205851932416][task_id:django.request][log.py:228][ERROR][Internal Server Error: /consul/remotehttp]
Traceback (most recent call last):
  File "/opt/code/env/python/python3-django/venv/lib/python3.7/site-packages/django/core/handlers/exception.py", line 34, in inner
    response = get_response(request)
  File "/opt/code/env/python/python3-django/venv/lib/python3.7/site-packages/django/core/handlers/base.py", line 126, in _get_response
    response = self.process_exception_by_middleware(e, request)
  File "/opt/code/env/python/python3-django/venv/lib/python3.7/site-packages/django/core/handlers/base.py", line 124, in _get_response
    response = wrapped_callback(request, *callback_args, **callback_kwargs)
  File "/opt/code/git/repository/devopsV2/myhttp/myviews/views.py", line 37, in remotehttp
    return(HttpResponse(redate.decode('utf-8')))
AttributeError: 'dict' object has no attribute 'decode'
[2019-04-22 07:33:54,743][Thread-1:140205851932416][task_id:django.server][basehttp.py:136][ERROR]["GET /consul/remotehttp HTTP/1.1" 500 67233]
[2019-04-22 07:35:14,322][Thread-1:139634592761600][task_id:root][viewmyhttp.py:38][ERROR][name 'rreturn' is not defined]
[2019-04-22 07:35:14,371][Thread-1:139634592761600][task_id:django.request][log.py:228][ERROR][Internal Server Error: /consul/remotehttp]
Traceback (most recent call last):
  File "/opt/code/env/python/python3-django/venv/lib/python3.7/site-packages/django/core/handlers/exception.py", line 34, in inner
    response = get_response(request)
  File "/opt/code/env/python/python3-django/venv/lib/python3.7/site-packages/django/core/handlers/base.py", line 126, in _get_response
    response = self.process_exception_by_middleware(e, request)
  File "/opt/code/env/python/python3-django/venv/lib/python3.7/site-packages/django/core/handlers/base.py", line 124, in _get_response
    response = wrapped_callback(request, *callback_args, **callback_kwargs)
  File "/opt/code/git/repository/devopsV2/myhttp/myviews/views.py", line 37, in remotehttp
    return(HttpResponse(redate.decode('utf-8')))
AttributeError: 'dict' object has no attribute 'decode'
[2019-04-22 07:35:14,372][Thread-1:139634592761600][task_id:django.server][basehttp.py:136][ERROR]["GET /consul/remotehttp HTTP/1.1" 500 67233]
[2019-04-22 07:35:18,254][Thread-1:139634592761600][task_id:root][viewmyhttp.py:38][ERROR][name 'rreturn' is not defined]
[2019-04-22 07:35:18,309][Thread-1:139634592761600][task_id:django.request][log.py:228][ERROR][Internal Server Error: /consul/remotehttp]
Traceback (most recent call last):
  File "/opt/code/env/python/python3-django/venv/lib/python3.7/site-packages/django/core/handlers/exception.py", line 34, in inner
    response = get_response(request)
  File "/opt/code/env/python/python3-django/venv/lib/python3.7/site-packages/django/core/handlers/base.py", line 126, in _get_response
    response = self.process_exception_by_middleware(e, request)
  File "/opt/code/env/python/python3-django/venv/lib/python3.7/site-packages/django/core/handlers/base.py", line 124, in _get_response
    response = wrapped_callback(request, *callback_args, **callback_kwargs)
  File "/opt/code/git/repository/devopsV2/myhttp/myviews/views.py", line 37, in remotehttp
    return(HttpResponse(redate.decode('utf-8')))
AttributeError: 'dict' object has no attribute 'decode'
[2019-04-22 07:35:18,309][Thread-1:139634592761600][task_id:django.server][basehttp.py:136][ERROR]["GET /consul/remotehttp HTTP/1.1" 500 67233]
[2019-04-22 07:35:24,260][Thread-3:139943441315584][task_id:django.request][log.py:228][ERROR][Internal Server Error: /consul/remotehttp]
Traceback (most recent call last):
  File "/opt/code/env/python/python3-django/venv/lib/python3.7/site-packages/django/core/handlers/exception.py", line 34, in inner
    response = get_response(request)
  File "/opt/code/env/python/python3-django/venv/lib/python3.7/site-packages/django/core/handlers/base.py", line 126, in _get_response
    response = self.process_exception_by_middleware(e, request)
  File "/opt/code/env/python/python3-django/venv/lib/python3.7/site-packages/django/core/handlers/base.py", line 124, in _get_response
    response = wrapped_callback(request, *callback_args, **callback_kwargs)
  File "/opt/code/git/repository/devopsV2/myhttp/myviews/views.py", line 37, in remotehttp
    return(HttpResponse(redate.decode('utf-8')))
AttributeError: 'JsonResponse' object has no attribute 'decode'
[2019-04-22 07:35:24,261][Thread-3:139943441315584][task_id:django.server][basehttp.py:136][ERROR]["GET /consul/remotehttp HTTP/1.1" 500 66846]
[2019-04-22 07:40:43,817][Thread-3:140217431467776][task_id:django.request][log.py:228][ERROR][Internal Server Error: /consul/remotehttp]
Traceback (most recent call last):
  File "/opt/code/env/python/python3-django/venv/lib/python3.7/site-packages/django/core/handlers/exception.py", line 34, in inner
    response = get_response(request)
  File "/opt/code/env/python/python3-django/venv/lib/python3.7/site-packages/django/core/handlers/base.py", line 126, in _get_response
    response = self.process_exception_by_middleware(e, request)
  File "/opt/code/env/python/python3-django/venv/lib/python3.7/site-packages/django/core/handlers/base.py", line 124, in _get_response
    response = wrapped_callback(request, *callback_args, **callback_kwargs)
  File "/opt/code/git/repository/devopsV2/myhttp/myviews/views.py", line 37, in remotehttp
    return(HttpResponse(redate.decode('utf-8')))
AttributeError: 'JsonResponse' object has no attribute 'decode'
[2019-04-22 07:40:43,819][Thread-3:140217431467776][task_id:django.server][basehttp.py:136][ERROR]["GET /consul/remotehttp HTTP/1.1" 500 66846]
[2019-04-22 07:40:47,780][Thread-3:140217431467776][task_id:django.request][log.py:228][ERROR][Internal Server Error: /consul/remotehttp]
Traceback (most recent call last):
  File "/opt/code/env/python/python3-django/venv/lib/python3.7/site-packages/django/core/handlers/exception.py", line 34, in inner
    response = get_response(request)
  File "/opt/code/env/python/python3-django/venv/lib/python3.7/site-packages/django/core/handlers/base.py", line 126, in _get_response
    response = self.process_exception_by_middleware(e, request)
  File "/opt/code/env/python/python3-django/venv/lib/python3.7/site-packages/django/core/handlers/base.py", line 124, in _get_response
    response = wrapped_callback(request, *callback_args, **callback_kwargs)
  File "/opt/code/git/repository/devopsV2/myhttp/myviews/views.py", line 37, in remotehttp
    return(HttpResponse(redate.decode('utf-8')))
AttributeError: 'JsonResponse' object has no attribute 'decode'
[2019-04-22 07:40:47,781][Thread-3:140217431467776][task_id:django.server][basehttp.py:136][ERROR]["GET /consul/remotehttp HTTP/1.1" 500 66846]
[2019-04-22 07:41:40,050][Thread-1:140176995120896][task_id:django.request][log.py:228][ERROR][Internal Server Error: /consul/remotehttp]
Traceback (most recent call last):
  File "/opt/code/env/python/python3-django/venv/lib/python3.7/site-packages/django/core/handlers/exception.py", line 34, in inner
    response = get_response(request)
  File "/opt/code/env/python/python3-django/venv/lib/python3.7/site-packages/django/core/handlers/base.py", line 126, in _get_response
    response = self.process_exception_by_middleware(e, request)
  File "/opt/code/env/python/python3-django/venv/lib/python3.7/site-packages/django/core/handlers/base.py", line 124, in _get_response
    response = wrapped_callback(request, *callback_args, **callback_kwargs)
  File "/opt/code/git/repository/devopsV2/myhttp/myviews/views.py", line 37, in remotehttp
    return(HttpResponse(redate.decode('utf-8')))
AttributeError: 'JsonResponse' object has no attribute 'decode'
[2019-04-22 07:41:40,051][Thread-1:140176995120896][task_id:django.server][basehttp.py:136][ERROR]["GET /consul/remotehttp HTTP/1.1" 500 66846]
[2019-04-22 07:43:29,396][Thread-3:140051674748672][task_id:django.request][log.py:228][ERROR][Internal Server Error: /consul/remotehttp]
Traceback (most recent call last):
  File "/opt/code/env/python/python3-django/venv/lib/python3.7/site-packages/django/core/handlers/exception.py", line 34, in inner
    response = get_response(request)
  File "/opt/code/env/python/python3-django/venv/lib/python3.7/site-packages/django/core/handlers/base.py", line 126, in _get_response
    response = self.process_exception_by_middleware(e, request)
  File "/opt/code/env/python/python3-django/venv/lib/python3.7/site-packages/django/core/handlers/base.py", line 124, in _get_response
    response = wrapped_callback(request, *callback_args, **callback_kwargs)
  File "/opt/code/git/repository/devopsV2/myhttp/myviews/views.py", line 37, in remotehttp
    return(HttpResponse(redate.decode('utf-8')))
AttributeError: 'JsonResponse' object has no attribute 'decode'
[2019-04-22 07:43:29,397][Thread-3:140051674748672][task_id:django.server][basehttp.py:136][ERROR]["GET /consul/remotehttp HTTP/1.1" 500 66846]
[2019-04-22 07:45:31,871][Thread-1:139705174144768][task_id:django.request][log.py:228][ERROR][Internal Server Error: /consul/remotehttp]
Traceback (most recent call last):
  File "/opt/code/env/python/python3-django/venv/lib/python3.7/site-packages/django/core/handlers/exception.py", line 34, in inner
    response = get_response(request)
  File "/opt/code/env/python/python3-django/venv/lib/python3.7/site-packages/django/core/handlers/base.py", line 126, in _get_response
    response = self.process_exception_by_middleware(e, request)
  File "/opt/code/env/python/python3-django/venv/lib/python3.7/site-packages/django/core/handlers/base.py", line 124, in _get_response
    response = wrapped_callback(request, *callback_args, **callback_kwargs)
  File "/opt/code/git/repository/devopsV2/myhttp/myviews/views.py", line 37, in remotehttp
    return(HttpResponse(redate.decode('utf-8')))
AttributeError: 'JsonResponse' object has no attribute 'decode'
[2019-04-22 07:45:31,873][Thread-1:139705174144768][task_id:django.server][basehttp.py:136][ERROR]["GET /consul/remotehttp HTTP/1.1" 500 66846]
[2019-04-22 07:50:59,737][Thread-3:140542121608960][task_id:django.request][log.py:228][ERROR][Internal Server Error: /consul/remotehttp]
Traceback (most recent call last):
  File "/opt/code/env/python/python3-django/venv/lib/python3.7/site-packages/django/core/handlers/exception.py", line 34, in inner
    response = get_response(request)
  File "/opt/code/env/python/python3-django/venv/lib/python3.7/site-packages/django/core/handlers/base.py", line 126, in _get_response
    response = self.process_exception_by_middleware(e, request)
  File "/opt/code/env/python/python3-django/venv/lib/python3.7/site-packages/django/core/handlers/base.py", line 124, in _get_response
    response = wrapped_callback(request, *callback_args, **callback_kwargs)
  File "/opt/code/git/repository/devopsV2/myhttp/myviews/views.py", line 37, in remotehttp
    return(HttpResponse(redate.decode('utf-8')))
AttributeError: 'JsonResponse' object has no attribute 'decode'
[2019-04-22 07:50:59,738][Thread-3:140542121608960][task_id:django.server][basehttp.py:136][ERROR]["GET /consul/remotehttp HTTP/1.1" 500 66708]
[2019-04-22 07:51:02,663][Thread-3:140542121608960][task_id:django.request][log.py:228][ERROR][Internal Server Error: /consul/remotehttp]
Traceback (most recent call last):
  File "/opt/code/env/python/python3-django/venv/lib/python3.7/site-packages/django/core/handlers/exception.py", line 34, in inner
    response = get_response(request)
  File "/opt/code/env/python/python3-django/venv/lib/python3.7/site-packages/django/core/handlers/base.py", line 126, in _get_response
    response = self.process_exception_by_middleware(e, request)
  File "/opt/code/env/python/python3-django/venv/lib/python3.7/site-packages/django/core/handlers/base.py", line 124, in _get_response
    response = wrapped_callback(request, *callback_args, **callback_kwargs)
  File "/opt/code/git/repository/devopsV2/myhttp/myviews/views.py", line 37, in remotehttp
    return(HttpResponse(redate.decode('utf-8')))
AttributeError: 'JsonResponse' object has no attribute 'decode'
[2019-04-22 07:51:02,664][Thread-3:140542121608960][task_id:django.server][basehttp.py:136][ERROR]["GET /consul/remotehttp HTTP/1.1" 500 66708]
[2019-04-22 07:51:20,441][Thread-3:140542121608960][task_id:django.request][log.py:228][ERROR][Internal Server Error: /consul/remotehttp]
Traceback (most recent call last):
  File "/opt/code/env/python/python3-django/venv/lib/python3.7/site-packages/django/core/handlers/exception.py", line 34, in inner
    response = get_response(request)
  File "/opt/code/env/python/python3-django/venv/lib/python3.7/site-packages/django/core/handlers/base.py", line 126, in _get_response
    response = self.process_exception_by_middleware(e, request)
  File "/opt/code/env/python/python3-django/venv/lib/python3.7/site-packages/django/core/handlers/base.py", line 124, in _get_response
    response = wrapped_callback(request, *callback_args, **callback_kwargs)
  File "/opt/code/git/repository/devopsV2/myhttp/myviews/views.py", line 37, in remotehttp
    return(HttpResponse(redate.decode('utf-8')))
AttributeError: 'JsonResponse' object has no attribute 'decode'
[2019-04-22 07:51:20,442][Thread-3:140542121608960][task_id:django.server][basehttp.py:136][ERROR]["GET /consul/remotehttp HTTP/1.1" 500 66708]
[2019-04-22 07:51:37,117][Thread-3:140542121608960][task_id:django.request][log.py:228][ERROR][Internal Server Error: /consul/remotehttp]
Traceback (most recent call last):
  File "/opt/code/env/python/python3-django/venv/lib/python3.7/site-packages/django/core/handlers/exception.py", line 34, in inner
    response = get_response(request)
  File "/opt/code/env/python/python3-django/venv/lib/python3.7/site-packages/django/core/handlers/base.py", line 126, in _get_response
    response = self.process_exception_by_middleware(e, request)
  File "/opt/code/env/python/python3-django/venv/lib/python3.7/site-packages/django/core/handlers/base.py", line 124, in _get_response
    response = wrapped_callback(request, *callback_args, **callback_kwargs)
  File "/opt/code/git/repository/devopsV2/myhttp/myviews/views.py", line 37, in remotehttp
    return(HttpResponse(redate.decode('utf-8')))
AttributeError: 'JsonResponse' object has no attribute 'decode'
[2019-04-22 07:51:37,117][Thread-3:140542121608960][task_id:django.server][basehttp.py:136][ERROR]["GET /consul/remotehttp HTTP/1.1" 500 66708]
[2019-04-22 07:51:50,443][Thread-1:140007728961280][task_id:django.request][log.py:228][ERROR][Internal Server Error: /consul/remotehttp]
Traceback (most recent call last):
  File "/opt/code/env/python/python3-django/venv/lib/python3.7/site-packages/django/core/handlers/exception.py", line 34, in inner
    response = get_response(request)
  File "/opt/code/env/python/python3-django/venv/lib/python3.7/site-packages/django/core/handlers/base.py", line 126, in _get_response
    response = self.process_exception_by_middleware(e, request)
  File "/opt/code/env/python/python3-django/venv/lib/python3.7/site-packages/django/core/handlers/base.py", line 124, in _get_response
    response = wrapped_callback(request, *callback_args, **callback_kwargs)
  File "/opt/code/git/repository/devopsV2/myhttp/myviews/views.py", line 37, in remotehttp
    return(HttpResponse(redate.decode('utf-8')))
AttributeError: 'JsonResponse' object has no attribute 'decode'
[2019-04-22 07:51:50,444][Thread-1:140007728961280][task_id:django.server][basehttp.py:136][ERROR]["GET /consul/remotehttp HTTP/1.1" 500 66846]
[2019-04-22 07:53:10,087][Thread-3:139774758196992][task_id:django.server][basehttp.py:136][INFO]["GET /consul/remotehttp HTTP/1.1" 200 14]
[2019-04-22 07:54:38,736][Thread-1:140202597463808][task_id:django.server][basehttp.py:136][INFO]["GET /consul/remotehttp HTTP/1.1" 200 284]
[2019-04-22 07:55:22,778][Thread-3:140398510835456][task_id:root][viewmyhttp.py:39][ERROR][dumps() argument after ** must be a mapping, not int]
[2019-04-22 07:55:22,826][Thread-3:140398510835456][task_id:django.request][log.py:228][ERROR][Internal Server Error: /consul/remotehttp]
Traceback (most recent call last):
  File "/opt/code/env/python/python3-django/venv/lib/python3.7/site-packages/django/core/handlers/exception.py", line 34, in inner
    response = get_response(request)
  File "/opt/code/env/python/python3-django/venv/lib/python3.7/site-packages/django/utils/deprecation.py", line 93, in __call__
    response = self.process_response(request, response)
  File "/opt/code/env/python/python3-django/venv/lib/python3.7/site-packages/django/middleware/common.py", line 105, in process_response
    if response.status_code == 404:
AttributeError: 'dict' object has no attribute 'status_code'
[2019-04-22 07:55:22,827][Thread-3:140398510835456][task_id:django.server][basehttp.py:136][ERROR]["GET /consul/remotehttp HTTP/1.1" 500 61466]
[2019-04-22 07:55:56,617][Thread-1:140376158807808][task_id:django.server][basehttp.py:136][INFO]["GET /consul/remotehttp HTTP/1.1" 200 284]
[2019-04-22 08:03:21,896][Thread-1:139930661074688][task_id:django.server][basehttp.py:136][INFO]["GET /consul/remotehttp HTTP/1.1" 200 284]
[2019-04-22 08:04:45,142][Thread-1:139895618754304][task_id:root][viewmyhttp.py:38][ERROR]['JsonResponse' object has no attribute 'decode']
[2019-04-22 08:04:45,184][Thread-1:139895618754304][task_id:django.request][log.py:228][ERROR][Internal Server Error: /consul/remotehttp]
Traceback (most recent call last):
  File "/opt/code/env/python/python3-django/venv/lib/python3.7/site-packages/django/core/handlers/exception.py", line 34, in inner
    response = get_response(request)
  File "/opt/code/env/python/python3-django/venv/lib/python3.7/site-packages/django/core/handlers/base.py", line 126, in _get_response
    response = self.process_exception_by_middleware(e, request)
  File "/opt/code/env/python/python3-django/venv/lib/python3.7/site-packages/django/core/handlers/base.py", line 124, in _get_response
    response = wrapped_callback(request, *callback_args, **callback_kwargs)
  File "/opt/code/git/repository/devopsV2/myhttp/myviews/views.py", line 36, in remotehttp
    redate = data.http_get()
  File "/opt/code/git/repository/devopsV2/myhttp/myviews/viewmyhttp.py", line 39, in http_get
    return(HttpResponse(myresponse.decode('utf-8')))
AttributeError: 'JsonResponse' object has no attribute 'decode'
[2019-04-22 08:04:45,186][Thread-1:139895618754304][task_id:django.server][basehttp.py:136][ERROR]["GET /consul/remotehttp HTTP/1.1" 500 71177]
[2019-04-22 08:05:12,466][Thread-1:140540419757824][task_id:django.server][basehttp.py:136][INFO]["GET /consul/remotehttp HTTP/1.1" 200 284]
[2019-04-22 08:05:16,292][Thread-1:140540419757824][task_id:django.server][basehttp.py:136][INFO]["GET /consul/remotehttp HTTP/1.1" 200 284]
[2019-04-22 08:05:19,855][Thread-1:140540419757824][task_id:django.server][basehttp.py:136][INFO]["GET /consul/remotehttp HTTP/1.1" 200 284]
[2019-04-22 08:06:12,753][Thread-1:139816284976896][task_id:django.server][basehttp.py:136][INFO]["GET /consul/remotehttp HTTP/1.1" 200 284]
[2019-04-22 08:06:15,719][Thread-1:139816284976896][task_id:django.server][basehttp.py:136][INFO]["GET /consul/remotehttp HTTP/1.1" 200 284]
[2019-04-22 08:06:18,431][Thread-1:139816284976896][task_id:django.server][basehttp.py:136][INFO]["GET /consul/remotehttp HTTP/1.1" 200 284]
[2019-04-22 08:10:49,308][Thread-1:139924773058304][task_id:django.server][basehttp.py:136][INFO]["GET /consul/remotehttp HTTP/1.1" 200 284]
[2019-04-22 08:12:28,889][Thread-1:140391998617344][task_id:root][viewmyhttp.py:39][ERROR][__init__() got an unexpected keyword argument 'indent']
[2019-04-22 08:12:28,928][Thread-1:140391998617344][task_id:django.request][log.py:228][ERROR][Internal Server Error: /consul/remotehttp]
Traceback (most recent call last):
  File "/opt/code/env/python/python3-django/venv/lib/python3.7/site-packages/django/core/handlers/exception.py", line 34, in inner
    response = get_response(request)
  File "/opt/code/env/python/python3-django/venv/lib/python3.7/site-packages/django/core/handlers/base.py", line 126, in _get_response
    response = self.process_exception_by_middleware(e, request)
  File "/opt/code/env/python/python3-django/venv/lib/python3.7/site-packages/django/core/handlers/base.py", line 124, in _get_response
    response = wrapped_callback(request, *callback_args, **callback_kwargs)
  File "/opt/code/git/repository/devopsV2/myhttp/myviews/views.py", line 36, in remotehttp
    redate = data.http_get()
  File "/opt/code/git/repository/devopsV2/myhttp/myviews/viewmyhttp.py", line 40, in http_get
    return(HttpResponse(myresponse.decode('utf-8')))
AttributeError: 'str' object has no attribute 'decode'
[2019-04-22 08:12:28,930][Thread-1:140391998617344][task_id:django.server][basehttp.py:136][ERROR]["GET /consul/remotehttp HTTP/1.1" 500 71655]
[2019-04-22 08:12:44,373][Thread-1:139762969659136][task_id:django.server][basehttp.py:136][INFO]["GET /consul/remotehttp HTTP/1.1" 200 284]
[2019-04-22 08:13:37,590][Thread-1:140460713793280][task_id:root][viewmyhttp.py:39][ERROR][__init__() got an unexpected keyword argument 'indent']
[2019-04-22 08:13:37,644][Thread-1:140460713793280][task_id:django.request][log.py:228][ERROR][Internal Server Error: /consul/remotehttp]
Traceback (most recent call last):
  File "/opt/code/env/python/python3-django/venv/lib/python3.7/site-packages/django/core/handlers/exception.py", line 34, in inner
    response = get_response(request)
  File "/opt/code/env/python/python3-django/venv/lib/python3.7/site-packages/django/core/handlers/base.py", line 126, in _get_response
    response = self.process_exception_by_middleware(e, request)
  File "/opt/code/env/python/python3-django/venv/lib/python3.7/site-packages/django/core/handlers/base.py", line 124, in _get_response
    response = wrapped_callback(request, *callback_args, **callback_kwargs)
  File "/opt/code/git/repository/devopsV2/myhttp/myviews/views.py", line 36, in remotehttp
    redate = data.http_get()
  File "/opt/code/git/repository/devopsV2/myhttp/myviews/viewmyhttp.py", line 40, in http_get
    return(HttpResponse(myresponse.decode('utf-8')))
AttributeError: 'str' object has no attribute 'decode'
[2019-04-22 08:13:37,645][Thread-1:140460713793280][task_id:django.server][basehttp.py:136][ERROR]["GET /consul/remotehttp HTTP/1.1" 500 71655]
[2019-04-22 08:13:51,271][Thread-1:140460713793280][task_id:root][viewmyhttp.py:39][ERROR][__init__() got an unexpected keyword argument 'indent']
[2019-04-22 08:13:51,307][Thread-1:140460713793280][task_id:django.request][log.py:228][ERROR][Internal Server Error: /consul/remotehttp]
Traceback (most recent call last):
  File "/opt/code/env/python/python3-django/venv/lib/python3.7/site-packages/django/core/handlers/exception.py", line 34, in inner
    response = get_response(request)
  File "/opt/code/env/python/python3-django/venv/lib/python3.7/site-packages/django/core/handlers/base.py", line 126, in _get_response
    response = self.process_exception_by_middleware(e, request)
  File "/opt/code/env/python/python3-django/venv/lib/python3.7/site-packages/django/core/handlers/base.py", line 124, in _get_response
    response = wrapped_callback(request, *callback_args, **callback_kwargs)
  File "/opt/code/git/repository/devopsV2/myhttp/myviews/views.py", line 36, in remotehttp
    redate = data.http_get()
  File "/opt/code/git/repository/devopsV2/myhttp/myviews/viewmyhttp.py", line 40, in http_get
    return(HttpResponse(myresponse.decode('utf-8')))
AttributeError: 'str' object has no attribute 'decode'
[2019-04-22 08:13:51,308][Thread-1:140460713793280][task_id:django.server][basehttp.py:136][ERROR]["GET /consul/remotehttp HTTP/1.1" 500 71655]
[2019-04-22 08:14:07,955][Thread-1:140460713793280][task_id:root][viewmyhttp.py:39][ERROR][__init__() got an unexpected keyword argument 'indent']
[2019-04-22 08:14:07,991][Thread-1:140460713793280][task_id:django.request][log.py:228][ERROR][Internal Server Error: /consul/remotehttp]
Traceback (most recent call last):
  File "/opt/code/env/python/python3-django/venv/lib/python3.7/site-packages/django/core/handlers/exception.py", line 34, in inner
    response = get_response(request)
  File "/opt/code/env/python/python3-django/venv/lib/python3.7/site-packages/django/core/handlers/base.py", line 126, in _get_response
    response = self.process_exception_by_middleware(e, request)
  File "/opt/code/env/python/python3-django/venv/lib/python3.7/site-packages/django/core/handlers/base.py", line 124, in _get_response
    response = wrapped_callback(request, *callback_args, **callback_kwargs)
  File "/opt/code/git/repository/devopsV2/myhttp/myviews/views.py", line 36, in remotehttp
    redate = data.http_get()
  File "/opt/code/git/repository/devopsV2/myhttp/myviews/viewmyhttp.py", line 40, in http_get
    return(HttpResponse(myresponse.decode('utf-8')))
AttributeError: 'str' object has no attribute 'decode'
[2019-04-22 08:14:07,992][Thread-1:140460713793280][task_id:django.server][basehttp.py:136][ERROR]["GET /consul/remotehttp HTTP/1.1" 500 71655]
[2019-04-22 08:15:47,222][Thread-3:140272818185984][task_id:django.server][basehttp.py:136][INFO]["GET /consul/remotehttp HTTP/1.1" 200 367]
[2019-04-22 08:16:01,239][Thread-1:140467611940608][task_id:django.server][basehttp.py:136][INFO]["GET /consul/remotehttp HTTP/1.1" 200 367]
[2019-04-22 08:16:04,343][Thread-1:140467611940608][task_id:django.server][basehttp.py:136][INFO]["GET /consul/remotehttp HTTP/1.1" 200 367]
[2019-04-22 08:16:16,282][Thread-1:139811026417408][task_id:django.server][basehttp.py:136][INFO]["GET /consul/remotehttp HTTP/1.1" 200 284]
[2019-04-22 08:18:44,539][Thread-1:139742523582208][task_id:django.request][log.py:228][ERROR][Internal Server Error: /consul/remotehttp]
Traceback (most recent call last):
  File "/opt/code/env/python/python3-django/venv/lib/python3.7/site-packages/django/core/handlers/exception.py", line 34, in inner
    response = get_response(request)
  File "/opt/code/env/python/python3-django/venv/lib/python3.7/site-packages/django/utils/deprecation.py", line 93, in __call__
    response = self.process_response(request, response)
  File "/opt/code/env/python/python3-django/venv/lib/python3.7/site-packages/django/middleware/clickjacking.py", line 26, in process_response
    if response.get('X-Frame-Options') is not None:
AttributeError: 'str' object has no attribute 'get'
[2019-04-22 08:18:44,540][Thread-1:139742523582208][task_id:django.server][basehttp.py:136][ERROR]["GET /consul/remotehttp HTTP/1.1" 500 61549]
[2019-04-22 08:19:12,320][Thread-1:139742523582208][task_id:django.request][log.py:228][ERROR][Internal Server Error: /consul/remotehttp]
Traceback (most recent call last):
  File "/opt/code/env/python/python3-django/venv/lib/python3.7/site-packages/django/core/handlers/exception.py", line 34, in inner
    response = get_response(request)
  File "/opt/code/env/python/python3-django/venv/lib/python3.7/site-packages/django/utils/deprecation.py", line 93, in __call__
    response = self.process_response(request, response)
  File "/opt/code/env/python/python3-django/venv/lib/python3.7/site-packages/django/middleware/clickjacking.py", line 26, in process_response
    if response.get('X-Frame-Options') is not None:
AttributeError: 'str' object has no attribute 'get'
[2019-04-22 08:19:12,321][Thread-1:139742523582208][task_id:django.server][basehttp.py:136][ERROR]["GET /consul/remotehttp HTTP/1.1" 500 61549]
[2019-04-22 08:19:46,690][Thread-3:140617220876032][task_id:django.request][log.py:228][ERROR][Internal Server Error: /consul/remotehttp]
Traceback (most recent call last):
  File "/opt/code/env/python/python3-django/venv/lib/python3.7/site-packages/django/core/handlers/exception.py", line 34, in inner
    response = get_response(request)
  File "/opt/code/env/python/python3-django/venv/lib/python3.7/site-packages/django/utils/deprecation.py", line 93, in __call__
    response = self.process_response(request, response)
  File "/opt/code/env/python/python3-django/venv/lib/python3.7/site-packages/django/middleware/common.py", line 105, in process_response
    if response.status_code == 404:
AttributeError: 'dict' object has no attribute 'status_code'
[2019-04-22 08:19:46,691][Thread-3:140617220876032][task_id:django.server][basehttp.py:136][ERROR]["GET /consul/remotehttp HTTP/1.1" 500 61466]
[2019-04-22 08:19:50,251][Thread-1:140617229268736][task_id:django.request][log.py:228][ERROR][Internal Server Error: /consul/remotehttp]
Traceback (most recent call last):
  File "/opt/code/env/python/python3-django/venv/lib/python3.7/site-packages/django/core/handlers/exception.py", line 34, in inner
    response = get_response(request)
  File "/opt/code/env/python/python3-django/venv/lib/python3.7/site-packages/django/utils/deprecation.py", line 93, in __call__
    response = self.process_response(request, response)
  File "/opt/code/env/python/python3-django/venv/lib/python3.7/site-packages/django/middleware/common.py", line 105, in process_response
    if response.status_code == 404:
AttributeError: 'dict' object has no attribute 'status_code'
[2019-04-22 08:19:50,252][Thread-1:140617229268736][task_id:django.server][basehttp.py:136][ERROR]["GET /consul/remotehttp HTTP/1.1" 500 61466]
[2019-04-22 08:21:18,030][Thread-1:139648462558976][task_id:django.server][basehttp.py:136][INFO]["GET /consul/remotehttp HTTP/1.1" 200 332]
[2019-04-22 08:22:09,282][Thread-1:140168785671936][task_id:django.server][basehttp.py:136][INFO]["GET /consul/remotehttp HTTP/1.1" 200 332]
[2019-04-22 08:23:04,792][Thread-1:140678445319936][task_id:django.server][basehttp.py:136][INFO]["GET /consul/remotehttp HTTP/1.1" 200 332]
[2019-04-22 08:23:30,363][Thread-1:140678445319936][task_id:django.server][basehttp.py:136][INFO]["GET /consul/remotehttp HTTP/1.1" 200 332]
[2019-04-22 08:34:36,706][Thread-1:140719006201600][task_id:django.server][basehttp.py:136][INFO]["GET /consul/remotehttp HTTP/1.1" 200 332]
[2019-04-23 09:33:34,535][Dummy-1:140702472537856][task_id:apscheduler.scheduler][base.py:440][INFO][Adding job tentatively -- it will be properly scheduled when the scheduler starts]
[2019-04-23 09:33:34,548][Dummy-1:140702472537856][task_id:apscheduler.scheduler][base.py:881][INFO][Added job "my_job" to job store "default"]
[2019-04-23 09:33:34,548][Dummy-1:140702472537856][task_id:apscheduler.scheduler][base.py:166][INFO][Scheduler started]
[2019-04-23 09:33:39,536][ThreadPoolExecutor-0_0:140702389368576][task_id:apscheduler.executors.default][base.py:123][INFO][Running job "my_job (trigger: interval[0:00:05], next run at: 2019-04-23 09:33:39 UTC)" (scheduled at 2019-04-23 09:33:39.535062+00:00)]
[2019-04-23 09:33:39,537][ThreadPoolExecutor-0_0:140702389368576][task_id:myhttp.myviews.views][views.py:17][INFO][2019-04-23 09:33:39]
[2019-04-23 09:33:39,537][ThreadPoolExecutor-0_0:140702389368576][task_id:apscheduler.executors.default][base.py:144][INFO][Job "my_job (trigger: interval[0:00:05], next run at: 2019-04-23 09:33:44 UTC)" executed successfully]
[2019-04-23 09:33:44,537][ThreadPoolExecutor-0_1:140702380975872][task_id:apscheduler.executors.default][base.py:123][INFO][Running job "my_job (trigger: interval[0:00:05], next run at: 2019-04-23 09:33:44 UTC)" (scheduled at 2019-04-23 09:33:44.535062+00:00)]
[2019-04-23 09:33:44,537][ThreadPoolExecutor-0_1:140702380975872][task_id:myhttp.myviews.views][views.py:17][INFO][2019-04-23 09:33:44]
[2019-04-23 09:33:44,537][ThreadPoolExecutor-0_1:140702380975872][task_id:apscheduler.executors.default][base.py:144][INFO][Job "my_job (trigger: interval[0:00:05], next run at: 2019-04-23 09:33:49 UTC)" executed successfully]
[2019-04-23 09:33:49,536][ThreadPoolExecutor-0_2:140702372583168][task_id:apscheduler.executors.default][base.py:123][INFO][Running job "my_job (trigger: interval[0:00:05], next run at: 2019-04-23 09:33:49 UTC)" (scheduled at 2019-04-23 09:33:49.535062+00:00)]
[2019-04-23 09:33:49,537][ThreadPoolExecutor-0_2:140702372583168][task_id:myhttp.myviews.views][views.py:17][INFO][2019-04-23 09:33:49]
[2019-04-23 09:33:49,537][ThreadPoolExecutor-0_2:140702372583168][task_id:apscheduler.executors.default][base.py:144][INFO][Job "my_job (trigger: interval[0:00:05], next run at: 2019-04-23 09:33:54 UTC)" executed successfully]
[2019-04-23 09:33:54,536][ThreadPoolExecutor-0_1:140702380975872][task_id:apscheduler.executors.default][base.py:123][INFO][Running job "my_job (trigger: interval[0:00:05], next run at: 2019-04-23 09:33:54 UTC)" (scheduled at 2019-04-23 09:33:54.535062+00:00)]
[2019-04-23 09:33:54,537][ThreadPoolExecutor-0_1:140702380975872][task_id:myhttp.myviews.views][views.py:17][INFO][2019-04-23 09:33:54]
[2019-04-23 09:33:54,537][ThreadPoolExecutor-0_1:140702380975872][task_id:apscheduler.executors.default][base.py:144][INFO][Job "my_job (trigger: interval[0:00:05], next run at: 2019-04-23 09:33:54 UTC)" executed successfully]
[2019-04-23 09:33:57,481][Dummy-1:140425864107776][task_id:apscheduler.scheduler][base.py:440][INFO][Adding job tentatively -- it will be properly scheduled when the scheduler starts]
[2019-04-23 09:33:57,487][Dummy-1:140425864107776][task_id:apscheduler.scheduler][base.py:881][INFO][Added job "my_job" to job store "default"]
[2019-04-23 09:33:57,488][Dummy-1:140425864107776][task_id:apscheduler.scheduler][base.py:166][INFO][Scheduler started]
[2019-04-23 19:33:57,482][ThreadPoolExecutor-0_0:140425848112896][task_id:apscheduler.executors.default][base.py:123][INFO][Running job "my_job (trigger: interval[10:00:00], next run at: 2019-04-23 19:33:57 UTC)" (scheduled at 2019-04-23 19:33:57.481311+00:00)]
[2019-04-23 19:33:57,482][ThreadPoolExecutor-0_0:140425848112896][task_id:myhttp.myviews.views][views.py:17][INFO][2019-04-23 19:33:57]
[2019-04-23 19:33:57,483][ThreadPoolExecutor-0_0:140425848112896][task_id:apscheduler.executors.default][base.py:144][INFO][Job "my_job (trigger: interval[10:00:00], next run at: 2019-04-24 05:33:57 UTC)" executed successfully]
[2019-04-24 08:30:25,332][Dummy-1:140185922373376][task_id:apscheduler.scheduler][base.py:440][INFO][Adding job tentatively -- it will be properly scheduled when the scheduler starts]
[2019-04-24 08:30:25,334][Dummy-1:140185922373376][task_id:apscheduler.scheduler][base.py:881][INFO][Added job "my_job" to job store "default"]
[2019-04-24 08:30:25,334][Dummy-1:140185922373376][task_id:apscheduler.scheduler][base.py:166][INFO][Scheduler started]
[2019-04-24 18:30:25,333][ThreadPoolExecutor-0_0:140185907689216][task_id:apscheduler.executors.default][base.py:123][INFO][Running job "my_job (trigger: interval[10:00:00], next run at: 2019-04-24 18:30:25 CST)" (scheduled at 2019-04-24 18:30:25.332491+08:00)]
[2019-04-24 18:30:25,333][ThreadPoolExecutor-0_0:140185907689216][task_id:myhttp.myviews.views][views.py:17][INFO][2019-04-24 18:30:25]
[2019-04-24 18:30:25,334][ThreadPoolExecutor-0_0:140185907689216][task_id:apscheduler.executors.default][base.py:144][INFO][Job "my_job (trigger: interval[10:00:00], next run at: 2019-04-25 04:30:25 CST)" executed successfully]
[2019-04-25 04:30:25,334][ThreadPoolExecutor-0_1:140185899296512][task_id:apscheduler.executors.default][base.py:123][INFO][Running job "my_job (trigger: interval[10:00:00], next run at: 2019-04-25 04:30:25 CST)" (scheduled at 2019-04-25 04:30:25.332491+08:00)]
[2019-04-25 04:30:25,335][ThreadPoolExecutor-0_1:140185899296512][task_id:myhttp.myviews.views][views.py:17][INFO][2019-04-25 04:30:25]
[2019-04-25 04:30:25,336][ThreadPoolExecutor-0_1:140185899296512][task_id:apscheduler.executors.default][base.py:144][INFO][Job "my_job (trigger: interval[10:00:00], next run at: 2019-04-25 14:30:25 CST)" executed successfully]
[2019-04-25 14:30:25,335][ThreadPoolExecutor-0_2:140185890903808][task_id:apscheduler.executors.default][base.py:123][INFO][Running job "my_job (trigger: interval[10:00:00], next run at: 2019-04-25 14:30:25 CST)" (scheduled at 2019-04-25 14:30:25.332491+08:00)]
[2019-04-25 14:30:25,335][ThreadPoolExecutor-0_2:140185890903808][task_id:myhttp.myviews.views][views.py:17][INFO][2019-04-25 14:30:25]
[2019-04-25 14:30:25,336][ThreadPoolExecutor-0_2:140185890903808][task_id:apscheduler.executors.default][base.py:144][INFO][Job "my_job (trigger: interval[10:00:00], next run at: 2019-04-26 00:30:25 CST)" executed successfully]
[2019-04-26 00:30:25,334][ThreadPoolExecutor-0_3:140185882511104][task_id:apscheduler.executors.default][base.py:123][INFO][Running job "my_job (trigger: interval[10:00:00], next run at: 2019-04-26 00:30:25 CST)" (scheduled at 2019-04-26 00:30:25.332491+08:00)]
[2019-04-26 00:30:25,335][ThreadPoolExecutor-0_3:140185882511104][task_id:myhttp.myviews.views][views.py:17][INFO][2019-04-26 00:30:25]
[2019-04-26 00:30:25,335][ThreadPoolExecutor-0_3:140185882511104][task_id:apscheduler.executors.default][base.py:144][INFO][Job "my_job (trigger: interval[10:00:00], next run at: 2019-04-26 10:30:25 CST)" executed successfully]
[2019-04-26 10:30:25,334][ThreadPoolExecutor-0_4:140185874118400][task_id:apscheduler.executors.default][base.py:123][INFO][Running job "my_job (trigger: interval[10:00:00], next run at: 2019-04-26 10:30:25 CST)" (scheduled at 2019-04-26 10:30:25.332491+08:00)]
[2019-04-26 10:30:25,335][ThreadPoolExecutor-0_4:140185874118400][task_id:myhttp.myviews.views][views.py:17][INFO][2019-04-26 10:30:25]
[2019-04-26 10:30:25,335][ThreadPoolExecutor-0_4:140185874118400][task_id:apscheduler.executors.default][base.py:144][INFO][Job "my_job (trigger: interval[10:00:00], next run at: 2019-04-26 20:30:25 CST)" executed successfully]
[2019-04-26 20:30:25,334][ThreadPoolExecutor-0_5:140185865725696][task_id:apscheduler.executors.default][base.py:123][INFO][Running job "my_job (trigger: interval[10:00:00], next run at: 2019-04-26 20:30:25 CST)" (scheduled at 2019-04-26 20:30:25.332491+08:00)]
[2019-04-26 20:30:25,334][ThreadPoolExecutor-0_5:140185865725696][task_id:myhttp.myviews.views][views.py:17][INFO][2019-04-26 20:30:25]
[2019-04-26 20:30:25,335][ThreadPoolExecutor-0_5:140185865725696][task_id:apscheduler.executors.default][base.py:144][INFO][Job "my_job (trigger: interval[10:00:00], next run at: 2019-04-27 06:30:25 CST)" executed successfully]
[2019-04-27 06:30:25,335][ThreadPoolExecutor-0_1:140185899296512][task_id:apscheduler.executors.default][base.py:123][INFO][Running job "my_job (trigger: interval[10:00:00], next run at: 2019-04-27 06:30:25 CST)" (scheduled at 2019-04-27 06:30:25.332491+08:00)]
[2019-04-27 06:30:25,335][ThreadPoolExecutor-0_1:140185899296512][task_id:myhttp.myviews.views][views.py:17][INFO][2019-04-27 06:30:25]
[2019-04-27 06:30:25,335][ThreadPoolExecutor-0_1:140185899296512][task_id:apscheduler.executors.default][base.py:144][INFO][Job "my_job (trigger: interval[10:00:00], next run at: 2019-04-27 06:30:25 CST)" executed successfully]
[2019-04-27 16:30:25,335][ThreadPoolExecutor-0_0:140185907689216][task_id:apscheduler.executors.default][base.py:123][INFO][Running job "my_job (trigger: interval[10:00:00], next run at: 2019-04-27 16:30:25 CST)" (scheduled at 2019-04-27 16:30:25.332491+08:00)]
[2019-04-27 16:30:25,335][ThreadPoolExecutor-0_0:140185907689216][task_id:myhttp.myviews.views][views.py:17][INFO][2019-04-27 16:30:25]
[2019-04-27 16:30:25,335][ThreadPoolExecutor-0_0:140185907689216][task_id:apscheduler.executors.default][base.py:144][INFO][Job "my_job (trigger: interval[10:00:00], next run at: 2019-04-27 16:30:25 CST)" executed successfully]
[2019-04-28 02:30:25,335][ThreadPoolExecutor-0_8:140185366943488][task_id:apscheduler.executors.default][base.py:123][INFO][Running job "my_job (trigger: interval[10:00:00], next run at: 2019-04-28 02:30:25 CST)" (scheduled at 2019-04-28 02:30:25.332491+08:00)]
[2019-04-28 02:30:25,335][ThreadPoolExecutor-0_8:140185366943488][task_id:myhttp.myviews.views][views.py:17][INFO][2019-04-28 02:30:25]
[2019-04-28 02:30:25,336][ThreadPoolExecutor-0_8:140185366943488][task_id:apscheduler.executors.default][base.py:144][INFO][Job "my_job (trigger: interval[10:00:00], next run at: 2019-04-28 12:30:25 CST)" executed successfully]
[2019-04-28 12:30:25,335][ThreadPoolExecutor-0_9:140185358550784][task_id:apscheduler.executors.default][base.py:123][INFO][Running job "my_job (trigger: interval[10:00:00], next run at: 2019-04-28 12:30:25 CST)" (scheduled at 2019-04-28 12:30:25.332491+08:00)]
[2019-04-28 12:30:25,335][ThreadPoolExecutor-0_9:140185358550784][task_id:myhttp.myviews.views][views.py:17][INFO][2019-04-28 12:30:25]
[2019-04-28 12:30:25,335][ThreadPoolExecutor-0_9:140185358550784][task_id:apscheduler.executors.default][base.py:144][INFO][Job "my_job (trigger: interval[10:00:00], next run at: 2019-04-28 12:30:25 CST)" executed successfully]
[2019-04-28 22:30:25,335][ThreadPoolExecutor-0_3:140185882511104][task_id:apscheduler.executors.default][base.py:123][INFO][Running job "my_job (trigger: interval[10:00:00], next run at: 2019-04-29 08:30:25 CST)" (scheduled at 2019-04-28 22:30:25.332491+08:00)]
[2019-04-28 22:30:25,335][ThreadPoolExecutor-0_3:140185882511104][task_id:myhttp.myviews.views][views.py:17][INFO][2019-04-28 22:30:25]
[2019-04-28 22:30:25,335][ThreadPoolExecutor-0_3:140185882511104][task_id:apscheduler.executors.default][base.py:144][INFO][Job "my_job (trigger: interval[10:00:00], next run at: 2019-04-29 08:30:25 CST)" executed successfully]
[2019-04-29 08:30:25,333][ThreadPoolExecutor-0_6:140185383728896][task_id:apscheduler.executors.default][base.py:123][INFO][Running job "my_job (trigger: interval[10:00:00], next run at: 2019-04-29 18:30:25 CST)" (scheduled at 2019-04-29 08:30:25.332491+08:00)]
[2019-04-29 08:30:25,334][ThreadPoolExecutor-0_6:140185383728896][task_id:myhttp.myviews.views][views.py:17][INFO][2019-04-29 08:30:25]
[2019-04-29 08:30:25,334][ThreadPoolExecutor-0_6:140185383728896][task_id:apscheduler.executors.default][base.py:144][INFO][Job "my_job (trigger: interval[10:00:00], next run at: 2019-04-29 18:30:25 CST)" executed successfully]
[2019-04-29 18:30:25,334][ThreadPoolExecutor-0_7:140185375336192][task_id:apscheduler.executors.default][base.py:123][INFO][Running job "my_job (trigger: interval[10:00:00], next run at: 2019-04-30 04:30:25 CST)" (scheduled at 2019-04-29 18:30:25.332491+08:00)]
[2019-04-29 18:30:25,335][ThreadPoolExecutor-0_7:140185375336192][task_id:myhttp.myviews.views][views.py:17][INFO][2019-04-29 18:30:25]
[2019-04-29 18:30:25,335][ThreadPoolExecutor-0_7:140185375336192][task_id:apscheduler.executors.default][base.py:144][INFO][Job "my_job (trigger: interval[10:00:00], next run at: 2019-04-30 04:30:25 CST)" executed successfully]
[2019-04-30 04:30:25,334][ThreadPoolExecutor-0_2:140185890903808][task_id:apscheduler.executors.default][base.py:123][INFO][Running job "my_job (trigger: interval[10:00:00], next run at: 2019-04-30 14:30:25 CST)" (scheduled at 2019-04-30 04:30:25.332491+08:00)]
[2019-04-30 04:30:25,334][ThreadPoolExecutor-0_2:140185890903808][task_id:myhttp.myviews.views][views.py:17][INFO][2019-04-30 04:30:25]
[2019-04-30 04:30:25,334][ThreadPoolExecutor-0_2:140185890903808][task_id:apscheduler.executors.default][base.py:144][INFO][Job "my_job (trigger: interval[10:00:00], next run at: 2019-04-30 14:30:25 CST)" executed successfully]
[2019-04-30 09:31:35,222][Dummy-1:139714443609856][task_id:apscheduler.scheduler][base.py:440][INFO][Adding job tentatively -- it will be properly scheduled when the scheduler starts]
[2019-04-30 09:31:35,225][Dummy-1:139714443609856][task_id:apscheduler.scheduler][base.py:881][INFO][Added job "my_job" to job store "default"]
[2019-04-30 09:31:35,225][Dummy-1:139714443609856][task_id:apscheduler.scheduler][base.py:166][INFO][Scheduler started]
[2019-04-30 10:36:47,518][Thread-1:140690999482112][task_id:django.server][basehttp.py:136][INFO]["GET /consul/remotehttp HTTP/1.1" 200 332]
[2019-04-30 10:36:47,800][Thread-1:140690999482112][task_id:django.request][log.py:228][WARNING][Not Found: /favicon.ico]
[2019-04-30 10:36:47,801][Thread-1:140690999482112][task_id:django.server][basehttp.py:136][WARNING]["GET /favicon.ico HTTP/1.1" 404 2313]
[2019-04-30 10:36:55,233][Thread-1:140690999482112][task_id:django.server][basehttp.py:136][INFO]["GET /consul/remotehttp HTTP/1.1" 200 332]
[2019-04-30 10:37:00,296][Thread-1:140690999482112][task_id:django.server][basehttp.py:136][INFO]["GET /consul/remotehttp HTTP/1.1" 200 332]
[2019-04-30 11:18:11,438][Thread-1:140528605157120][task_id:django.server][basehttp.py:136][INFO]["GET /consul/remotehttp HTTP/1.1" 200 332]
[2019-04-30 11:22:59,015][Thread-1:140144459065088][task_id:django.server][basehttp.py:136][INFO]["GET /consul/remotehttp HTTP/1.1" 200 332]
[2019-04-30 13:07:42,123][Dummy-1:140099094759168][task_id:apscheduler.scheduler][base.py:440][INFO][Adding job tentatively -- it will be properly scheduled when the scheduler starts]
[2019-04-30 13:07:42,124][Dummy-1:140099094759168][task_id:apscheduler.scheduler][base.py:881][INFO][Added job "my_job" to job store "default"]
[2019-04-30 13:07:42,125][Dummy-1:140099094759168][task_id:apscheduler.scheduler][base.py:166][INFO][Scheduler started]
[2019-04-30 13:08:04,564][Dummy-1:140241703999232][task_id:apscheduler.scheduler][base.py:440][INFO][Adding job tentatively -- it will be properly scheduled when the scheduler starts]
[2019-04-30 13:08:04,566][Dummy-1:140241703999232][task_id:apscheduler.scheduler][base.py:881][INFO][Added job "my_job" to job store "default"]
[2019-04-30 13:08:04,566][Dummy-1:140241703999232][task_id:apscheduler.scheduler][base.py:166][INFO][Scheduler started]
[2019-04-30 13:09:08,661][Dummy-1:139647211054848][task_id:apscheduler.scheduler][base.py:440][INFO][Adding job tentatively -- it will be properly scheduled when the scheduler starts]
[2019-04-30 13:09:08,663][Dummy-1:139647211054848][task_id:apscheduler.scheduler][base.py:881][INFO][Added job "my_job" to job store "default"]
[2019-04-30 13:09:08,664][Dummy-1:139647211054848][task_id:apscheduler.scheduler][base.py:166][INFO][Scheduler started]
[2019-04-30 13:13:03,327][Dummy-1:140062810838784][task_id:apscheduler.scheduler][base.py:440][INFO][Adding job tentatively -- it will be properly scheduled when the scheduler starts]
[2019-04-30 13:13:03,328][Dummy-1:140062810838784][task_id:apscheduler.scheduler][base.py:881][INFO][Added job "my_job" to job store "default"]
[2019-04-30 13:13:03,329][Dummy-1:140062810838784][task_id:apscheduler.scheduler][base.py:166][INFO][Scheduler started]
[2019-04-30 13:13:56,390][Dummy-1:140649418176256][task_id:apscheduler.scheduler][base.py:440][INFO][Adding job tentatively -- it will be properly scheduled when the scheduler starts]
[2019-04-30 13:13:56,392][Dummy-1:140649418176256][task_id:apscheduler.scheduler][base.py:881][INFO][Added job "my_job" to job store "default"]
[2019-04-30 13:13:56,392][Dummy-1:140649418176256][task_id:apscheduler.scheduler][base.py:166][INFO][Scheduler started]
[2019-04-30 13:14:25,411][Dummy-1:139999667943168][task_id:apscheduler.scheduler][base.py:440][INFO][Adding job tentatively -- it will be properly scheduled when the scheduler starts]
[2019-04-30 13:14:25,413][Dummy-1:139999667943168][task_id:apscheduler.scheduler][base.py:881][INFO][Added job "my_job" to job store "default"]
[2019-04-30 13:14:25,413][Dummy-1:139999667943168][task_id:apscheduler.scheduler][base.py:166][INFO][Scheduler started]
[2019-04-30 13:14:41,058][Dummy-1:139653431305984][task_id:apscheduler.scheduler][base.py:440][INFO][Adding job tentatively -- it will be properly scheduled when the scheduler starts]
[2019-04-30 13:14:41,059][Dummy-1:139653431305984][task_id:apscheduler.scheduler][base.py:881][INFO][Added job "my_job" to job store "default"]
[2019-04-30 13:14:41,060][Dummy-1:139653431305984][task_id:apscheduler.scheduler][base.py:166][INFO][Scheduler started]
[2019-04-30 13:14:45,035][Thread-2:139653313570560][task_id:django.server][basehttp.py:136][INFO]["GET /consul/remotehttp HTTP/1.1" 200 332]
[2019-04-30 13:28:47,206][Dummy-1:140550544905984][task_id:apscheduler.scheduler][base.py:440][INFO][Adding job tentatively -- it will be properly scheduled when the scheduler starts]
[2019-04-30 13:28:47,208][Dummy-1:140550544905984][task_id:apscheduler.scheduler][base.py:881][INFO][Added job "my_job" to job store "default"]
[2019-04-30 13:28:47,208][Dummy-1:140550544905984][task_id:apscheduler.scheduler][base.py:166][INFO][Scheduler started]
[2019-04-30 14:22:38,942][Thread-1:139960358954752][task_id:django.server][basehttp.py:136][INFO]["GET /consul/remotehttp HTTP/1.1" 200 332]
[2019-04-30 14:31:02,879][Thread-3:140084224673536][task_id:django.server][basehttp.py:136][INFO]["GET /consul/remotehttp HTTP/1.1" 200 332]
[2019-04-30 14:35:02,747][Dummy-1:139902952765184][task_id:apscheduler.scheduler][base.py:440][INFO][Adding job tentatively -- it will be properly scheduled when the scheduler starts]
[2019-04-30 14:35:02,749][Dummy-1:139902952765184][task_id:apscheduler.scheduler][base.py:881][INFO][Added job "my_job" to job store "default"]
[2019-04-30 14:35:02,749][Dummy-1:139902952765184][task_id:apscheduler.scheduler][base.py:166][INFO][Scheduler started]
[2019-04-30 14:35:07,287][Thread-2:139902833506048][task_id:django.server][basehttp.py:136][INFO]["GET /consul/remotehttp HTTP/1.1" 200 332]
[2019-04-30 14:40:31,823][Dummy-1:140122199787264][task_id:apscheduler.scheduler][base.py:440][INFO][Adding job tentatively -- it will be properly scheduled when the scheduler starts]
[2019-04-30 14:40:31,824][Dummy-1:140122199787264][task_id:apscheduler.scheduler][base.py:881][INFO][Added job "my_job" to job store "default"]
[2019-04-30 14:40:31,825][Dummy-1:140122199787264][task_id:apscheduler.scheduler][base.py:166][INFO][Scheduler started]
[2019-04-30 14:40:32,996][Thread-2:140122080339712][task_id:django.server][basehttp.py:136][INFO]["GET /consul/remotehttp HTTP/1.1" 200 332]
[2019-04-30 14:40:35,318][Thread-2:140122080339712][task_id:django.server][basehttp.py:136][INFO]["GET /consul/remotehttp HTTP/1.1" 200 332]
[2019-04-30 14:40:47,817][Dummy-1:139902634723072][task_id:apscheduler.scheduler][base.py:440][INFO][Adding job tentatively -- it will be properly scheduled when the scheduler starts]
[2019-04-30 14:40:47,818][Dummy-1:139902634723072][task_id:apscheduler.scheduler][base.py:881][INFO][Added job "my_job" to job store "default"]
[2019-04-30 14:40:47,819][Dummy-1:139902634723072][task_id:apscheduler.scheduler][base.py:166][INFO][Scheduler started]
